Workbook

Sheet 彩含价60319
A1: 对外型号 | B1: NP彩含60319 | C1: LP彩含60319 | D1: SLP彩含60319 | E1: 2S彩含60319 | F1: 3S彩含60319 | G1: 4S彩含60319 | H1: 属性 | I1: 通用名
A2: DQ910852 | B2: =VLOOKUP($A2,[1]彩含分析60315!$A:$M,8,0) -> 37 | C2: =VLOOKUP($A2,[1]彩含分析60315!$A:$M,9,0) -> 36 | D2: =VLOOKUP($A2,[1]彩含分析60315!$A:$M,10,0) -> 34 | E2: =VLOOKUP($A2,[1]彩含分析60315!$A:$M,11,0) -> 33 | F2: =VLOOKUP($A2,[1]彩含分析60315!$A:$M,12,0) -> 32 | G2: =VLOOKUP($A2,[1]彩含分析60315!$A:$M,13,0) -> 30 | H2: 自制 | I2: 丰田卡罗拉
A3: DQ9101B1 | B3: =VLOOKUP($A3,[1]彩含分析60315!$A:$M,8,0) -> 23 | C3: =VLOOKUP($A3,[1]彩含分析60315!$A:$M,9,0) -> 23 | D3: =VLOOKUP($A3,[1]彩含分析60315!$A:$M,10,0) -> 22 | E3: =VLOOKUP($A3,[1]彩含分析60315!$A:$M,11,0) -> 21 | F3: =VLOOKUP($A3,[1]彩含分析60315!$A:$M,12,0) -> 20 | G3: =VLOOKUP($A3,[1]彩含分析60315!$A:$M,13,0) -> 19 | H3: 自制 | I3: 伽玛发动机
A4: DQ9106L | B4: =VLOOKUP($A4,[1]彩含分析60315!$A:$M,8,0) -> 40 | C4: =VLOOKUP($A4,[1]彩含分析60315!$A:$M,9,0) -> 38 | D4: =VLOOKUP($A4,[1]彩含分析60315!$A:$M,10,0) -> 37 | E4: =VLOOKUP($A4,[1]彩含分析60315!$A:$M,11,0) -> 36 | F4: =VLOOKUP($A4,[1]彩含分析60315!$A:$M,12,0) -> 34 | G4: =VLOOKUP($A4,[1]彩含分析60315!$A:$M,13,0) -> 33 | H4: 自制 | I4: 波罗
A5: DQ9103A | B5: =VLOOKUP($A5,[1]彩含分析60315!$A:$M,8,0) -> 43 | C5: =VLOOKUP($A5,[1]彩含分析60315!$A:$M,9,0) -> 41 | D5: =VLOOKUP($A5,[1]彩含分析60315!$A:$M,10,0) -> 39 | E5: =VLOOKUP($A5,[1]彩含分析60315!$A:$M,11,0) -> 38 | F5: =VLOOKUP($A5,[1]彩含分析60315!$A:$M,12,0) -> 36 | G5: =VLOOKUP($A5,[1]彩含分析60315!$A:$M,13,0) -> 35 | H5: 自制 | I5: 奥迪C6
A6: DQ9101A | B6: =VLOOKUP($A6,[1]彩含分析60315!$A:$M,8,0) -> 23 | C6: =VLOOKUP($A6,[1]彩含分析60315!$A:$M,9,0) -> 23 | D6: =VLOOKUP($A6,[1]彩含分析60315!$A:$M,10,0) -> 22 | E6: =VLOOKUP($A6,[1]彩含分析60315!$A:$M,11,0) -> 21 | F6: =VLOOKUP($A6,[1]彩含分析60315!$A:$M,12,0) -> 20 | G6: =VLOOKUP($A6,[1]彩含分析60315!$A:$M,13,0) -> 19 | H6: 自制 | I6: 伊兰特 VVT 圆头
A7: DQ9115A | B7: =VLOOKUP($A7,[1]彩含分析60315!$A:$M,8,0) -> 25 | C7: =VLOOKUP($A7,[1]彩含分析60315!$A:$M,9,0) -> 24 | D7: =VLOOKUP($A7,[1]彩含分析60315!$A:$M,10,0) -> 23 | E7: =VLOOKUP($A7,[1]彩含分析60315!$A:$M,11,0) -> 22 | F7: =VLOOKUP($A7,[1]彩含分析60315!$A:$M,12,0) -> 21 | G7: =VLOOKUP($A7,[1]彩含分析60315!$A:$M,13,0) -> 20 | H7: 自制 | I7: 4A9
A8: DQ9012 | B8: =VLOOKUP($A8,[1]彩含分析60315!$A:$M,8,0) -> 43 | C8: =VLOOKUP($A8,[1]彩含分析60315!$A:$M,9,0) -> 41 | D8: =VLOOKUP($A8,[1]彩含分析60315!$A:$M,10,0) -> 40 | E8: =VLOOKUP($A8,[1]彩含分析60315!$A:$M,11,0) -> 38 | F8: =VLOOKUP($A8,[1]彩含分析60315!$A:$M,12,0) -> 37 | G8: =VLOOKUP($A8,[1]彩含分析60315!$A:$M,13,0) -> 35 | H8: 自制 | I8: 骐达
A9: DQ9219A | B9: =VLOOKUP($A9,[1]彩含分析60315!$A:$M,8,0) -> 29 | C9: =VLOOKUP($A9,[1]彩含分析60315!$A:$M,9,0) -> 28 | D9: =VLOOKUP($A9,[1]彩含分析60315!$A:$M,10,0) -> 27 | E9: =VLOOKUP($A9,[1]彩含分析60315!$A:$M,11,0) -> 26 | F9: =VLOOKUP($A9,[1]彩含分析60315!$A:$M,12,0) -> 25 | G9: =VLOOKUP($A9,[1]彩含分析60315!$A:$M,13,0) -> 24 | H9: 自制 | I9: 哈弗H6 1.5T
A10: DQ9103D | B10: =VLOOKUP($A10,[1]彩含分析60315!$A:$M,8,0) -> 42 | C10: =VLOOKUP($A10,[1]彩含分析60315!$A:$M,9,0) -> 41 | D10: =VLOOKUP($A10,[1]彩含分析60315!$A:$M,10,0) -> 39 | E10: =VLOOKUP($A10,[1]彩含分析60315!$A:$M,11,0) -> 37 | F10: =VLOOKUP($A10,[1]彩含分析60315!$A:$M,12,0) -> 36 | G10: =VLOOKUP($A10,[1]彩含分析60315!$A:$M,13,0) -> 34 | H10: 自制 | I10: 帕萨特B5 不铣胶面
A11: DQ910848 | B11: =VLOOKUP($A11,[1]彩含分析60315!$A:$M,8,0) -> 36 | C11: =VLOOKUP($A11,[1]彩含分析60315!$A:$M,9,0) -> 34 | D11: =VLOOKUP($A11,[1]彩含分析60315!$A:$M,10,0) -> 33 | E11: =VLOOKUP($A11,[1]彩含分析60315!$A:$M,11,0) -> 32 | F11: =VLOOKUP($A11,[1]彩含分析60315!$A:$M,12,0) -> 30 | G11: =VLOOKUP($A11,[1]彩含分析60315!$A:$M,13,0) -> 29 | H11: 自制 | I11: 丰田02248
A12: DQ9003H2 | B12: =VLOOKUP($A12,[1]彩含分析60315!$A:$M,8,0) -> 36 | C12: =VLOOKUP($A12,[1]彩含分析60315!$A:$M,9,0) -> 34 | D12: =VLOOKUP($A12,[1]彩含分析60315!$A:$M,10,0) -> 33 | E12: =VLOOKUP($A12,[1]彩含分析60315!$A:$M,11,0) -> 32 | F12: =VLOOKUP($A12,[1]彩含分析60315!$A:$M,12,0) -> 30 | G12: =VLOOKUP($A12,[1]彩含分析60315!$A:$M,13,0) -> 29 | H12: 自制 | I12: 尼桑
A13: DQ9401 | B13: =VLOOKUP($A13,[1]彩含分析60315!$A:$M,8,0) -> 43 | C13: =VLOOKUP($A13,[1]彩含分析60315!$A:$M,9,0) -> 41 | D13: =VLOOKUP($A13,[1]彩含分析60315!$A:$M,10,0) -> 39 | E13: =VLOOKUP($A13,[1]彩含分析60315!$A:$M,11,0) -> 38 | F13: =VLOOKUP($A13,[1]彩含分析60315!$A:$M,12,0) -> 36 | G13: =VLOOKUP($A13,[1]彩含分析60315!$A:$M,13,0) -> 35 | H13: 自制 | I13: 德尔福三代
... A473: DQ9003J2 | B473: =VLOOKUP($A473,[1]彩含分析60315!$A:$M,8,0) -> 49 | C473: =VLOOKUP($A473,[1]彩含分析60315!$A:$M,9,0) -> 47 | D473: =VLOOKUP($A473,[1]彩含分析60315!$A:$M,10,0) -> 45 | E473: =VLOOKUP($A473,[1]彩含分析60315!$A:$M,11,0) -> 44 | F473: =VLOOKUP($A473,[1]彩含分析60315!$A:$M,12,0) -> 42 | G473: =VLOOKUP($A473,[1]彩含分析60315!$A:$M,13,0) -> 40 | H473: 自制 | I473: 途乐4.0L
A474: DQ9003K1 | B474: =VLOOKUP($A474,[1]彩含分析60315!$A:$M,8,0) -> 55 | C474: =VLOOKUP($A474,[1]彩含分析60315!$A:$M,9,0) -> 54 | D474: =VLOOKUP($A474,[1]彩含分析60315!$A:$M,10,0) -> 53 | E474: =VLOOKUP($A474,[1]彩含分析60315!$A:$M,11,0) -> 52 | F474: =VLOOKUP($A474,[1]彩含分析60315!$A:$M,12,0) -> 52 | G474: =VLOOKUP($A474,[1]彩含分析60315!$A:$M,13,0) -> 51 | H474: 调货 | I474: 0
A475: DQ9004D2 | B475: =VLOOKUP($A475,[1]彩含分析60315!$A:$M,8,0) -> 41 | C475: =VLOOKUP($A475,[1]彩含分析60315!$A:$M,9,0) -> 40 | D475: =VLOOKUP($A475,[1]彩含分析60315!$A:$M,10,0) -> 38 | E475: =VLOOKUP($A475,[1]彩含分析60315!$A:$M,11,0) -> 37 | F475: =VLOOKUP($A475,[1]彩含分析60315!$A:$M,12,0) -> 35 | G475: =VLOOKUP($A475,[1]彩含分析60315!$A:$M,13,0) -> 34 | H475: 自制 | I475: 尼桑
A476: DQ9005M1 | B476: =VLOOKUP($A476,[1]彩含分析60315!$A:$M,8,0) -> 30 | C476: =VLOOKUP($A476,[1]彩含分析60315!$A:$M,9,0) -> 30 | D476: =VLOOKUP($A476,[1]彩含分析60315!$A:$M,10,0) -> 29 | E476: =VLOOKUP($A476,[1]彩含分析60315!$A:$M,11,0) -> 29 | F476: =VLOOKUP($A476,[1]彩含分析60315!$A:$M,12,0) -> 28 | G476: =VLOOKUP($A476,[1]彩含分析60315!$A:$M,13,0) -> 28 | H476: 调货 | I476: 福特96-99
A477: DQ9007J1 | B477: =VLOOKUP($A477,[1]彩含分析60315!$A:$M,8,0) -> 47 | C477: =VLOOKUP($A477,[1]彩含分析60315!$A:$M,9,0) -> 46 | D477: =VLOOKUP($A477,[1]彩含分析60315!$A:$M,10,0) -> 44 | E477: =VLOOKUP($A477,[1]彩含分析60315!$A:$M,11,0) -> 42 | F477: =VLOOKUP($A477,[1]彩含分析60315!$A:$M,12,0) -> 40 | G477: =VLOOKUP($A477,[1]彩含分析60315!$A:$M,13,0) -> 39 | H477: 自制 | I477: 现代3L030
A478: DQ9007H1 | B478: =VLOOKUP($A478,[1]彩含分析60315!$A:$M,8,0) -> 48 | C478: =VLOOKUP($A478,[1]彩含分析60315!$A:$M,9,0) -> 47 | D478: =VLOOKUP($A478,[1]彩含分析60315!$A:$M,10,0) -> 45 | E478: =VLOOKUP($A478,[1]彩含分析60315!$A:$M,11,0) -> 43 | F478: =VLOOKUP($A478,[1]彩含分析60315!$A:$M,12,0) -> 41 | G478: =VLOOKUP($A478,[1]彩含分析60315!$A:$M,13,0) -> 40 | H478: 自制 | I478: 2019 Kia Cadenza 3.3l
A479: DQ9008A1 | B479: =VLOOKUP($A479,[1]彩含分析60315!$A:$M,8,0) -> 48 | C479: =VLOOKUP($A479,[1]彩含分析60315!$A:$M,9,0) -> 47 | D479: =VLOOKUP($A479,[1]彩含分析60315!$A:$M,10,0) -> 46 | E479: =VLOOKUP($A479,[1]彩含分析60315!$A:$M,11,0) -> 45 | F479: =VLOOKUP($A479,[1]彩含分析60315!$A:$M,12,0) -> 45 | G479: =VLOOKUP($A479,[1]彩含分析60315!$A:$M,13,0) -> 44 | H479: 调货 | I479: 三菱蓝瑟4G93
A480: DQ9008B1 | B480: =VLOOKUP($A480,[1]彩含分析60315!$A:$M,8,0) -> 54 | C480: =VLOOKUP($A480,[1]彩含分析60315!$A:$M,9,0) -> 53 | D480: =VLOOKUP($A480,[1]彩含分析60315!$A:$M,10,0) -> 52 | E480: =VLOOKUP($A480,[1]彩含分析60315!$A:$M,11,0) -> 51 | F480: =VLOOKUP($A480,[1]彩含分析60315!$A:$M,12,0) -> 50 | G480: =VLOOKUP($A480,[1]彩含分析60315!$A:$M,13,0) -> 49 | H480: 调货 | I480: 三菱蓝瑟08-12 2.0L
A481: DQ9010G1 | B481: =VLOOKUP($A481,[1]彩含分析60315!$A:$M,8,0) -> 47 | C481: =VLOOKUP($A481,[1]彩含分析60315!$A:$M,9,0) -> 45 | D481: =VLOOKUP($A481,[1]彩含分析60315!$A:$M,10,0) -> 43 | E481: =VLOOKUP($A481,[1]彩含分析60315!$A:$M,11,0) -> 41 | F481: =VLOOKUP($A481,[1]彩含分析60315!$A:$M,12,0) -> 40 | G481: =VLOOKUP($A481,[1]彩含分析60315!$A:$M,13,0) -> 38 | H481: 自制 | I481: 本田锋范
A482: DQ9010L1 | B482: =VLOOKUP($A482,[1]彩含分析60315!$A:$M,8,0) -> 37 | C482: =VLOOKUP($A482,[1]彩含分析60315!$A:$M,9,0) -> 35 | D482: =VLOOKUP($A482,[1]彩含分析60315!$A:$M,10,0) -> 34 | E482: =VLOOKUP($A482,[1]彩含分析60315!$A:$M,11,0) -> 33 | F482: =VLOOKUP($A482,[1]彩含分析60315!$A:$M,12,0) -> 31 | G482: =VLOOKUP($A482,[1]彩含分析60315!$A:$M,13,0) -> 30 | H482: 自制 | I482: 本田飞度混动2013款
A483: DQ901810 | B483: =VLOOKUP($A483,[1]彩含分析60315!$A:$M,8,0) -> 59 | C483: =VLOOKUP($A483,[1]彩含分析60315!$A:$M,9,0) -> 58 | D483: =VLOOKUP($A483,[1]彩含分析60315!$A:$M,10,0) -> 57 | E483: =VLOOKUP($A483,[1]彩含分析60315!$A:$M,11,0) -> 56 | F483: =VLOOKUP($A483,[1]彩含分析60315!$A:$M,12,0) -> 56 | G483: =VLOOKUP($A483,[1]彩含分析60315!$A:$M,13,0) -> 55 | H483: 调货 | I483: 丰田2017-201818致炫
A484: DQ9024 | B484: =VLOOKUP($A484,[1]彩含分析60315!$A:$M,8,0) -> 78 | C484: =VLOOKUP($A484,[1]彩含分析60315!$A:$M,9,0) -> 76 | D484: =VLOOKUP($A484,[1]彩含分析60315!$A:$M,10,0) -> 75 | E484: =VLOOKUP($A484,[1]彩含分析60315!$A:$M,11,0) -> 74 | F484: =VLOOKUP($A484,[1]彩含分析60315!$A:$M,12,0) -> 73 | G484: =VLOOKUP($A484,[1]彩含分析60315!$A:$M,13,0) -> 72 | H484: 调货 | I484: 竞技 骑兵
A485: DQ9030C1 | B485: =VLOOKUP($A485,[1]彩含分析60315!$A:$M,8,0) -> 52 | C485: =VLOOKUP($A485,[1]彩含分析60315!$A:$M,9,0) -> 50 | D485: =VLOOKUP($A485,[1]彩含分析60315!$A:$M,10,0) -> 48 | E485: =VLOOKUP($A485,[1]彩含分析60315!$A:$M,11,0) -> 46 | F485: =VLOOKUP($A485,[1]彩含分析60315!$A:$M,12,0) -> 44 | G485: =VLOOKUP($A485,[1]彩含分析60315!$A:$M,13,0) -> 42 | H485: 自制 | I485: 长安福特 金牛座2.7T
A486: DQ9034A3 | B486: =VLOOKUP($A486,[1]彩含分析60315!$A:$M,8,0) -> 38 | C486: =VLOOKUP($A486,[1]彩含分析60315!$A:$M,9,0) -> 36 | D486: =VLOOKUP($A486,[1]彩含分析60315!$A:$M,10,0) -> 35 | E486: =VLOOKUP($A486,[1]彩含分析60315!$A:$M,11,0) -> 34 | F486: =VLOOKUP($A486,[1]彩含分析60315!$A:$M,12,0) -> 32 | G486: =VLOOKUP($A486,[1]彩含分析60315!$A:$M,13,0) -> 31 | H486: 自制 | I486: 纳智捷TT26S
... A548: DQ4202A1 | B548: =VLOOKUP($A548,[1]彩含分析60315!$A:$M,8,0) -> 63 | C548: =VLOOKUP($A548,[1]彩含分析60315!$A:$M,9,0) -> 62 | D548: =VLOOKUP($A548,[1]彩含分析60315!$A:$M,10,0) -> 61 | E548: =VLOOKUP($A548,[1]彩含分析60315!$A:$M,11,0) -> 60 | F548: =VLOOKUP($A548,[1]彩含分析60315!$A:$M,12,0) -> 60 | G548: =VLOOKUP($A548,[1]彩含分析60315!$A:$M,13,0) -> 59 | H548: 调货 | I548: 丰田SR40
A549: DQ4106A1 | B549: =VLOOKUP($A549,[1]彩含分析60315!$A:$M,8,0) -> 48 | C549: =VLOOKUP($A549,[1]彩含分析60315!$A:$M,9,0) -> 46 | D549: =VLOOKUP($A549,[1]彩含分析60315!$A:$M,10,0) -> 44 | E549: =VLOOKUP($A549,[1]彩含分析60315!$A:$M,11,0) -> 43 | F549: =VLOOKUP($A549,[1]彩含分析60315!$A:$M,12,0) -> 41 | G549: =VLOOKUP($A549,[1]彩含分析60315!$A:$M,13,0) -> 39 | H549: 自制 | I549: 12713668
A550: DQ4115A1 | B550: =VLOOKUP($A550,[1]彩含分析60315!$A:$M,8,0) -> 42 | C550: =VLOOKUP($A550,[1]彩含分析60315!$A:$M,9,0) -> 41 | D550: =VLOOKUP($A550,[1]彩含分析60315!$A:$M,10,0) -> 40 | E550: =VLOOKUP($A550,[1]彩含分析60315!$A:$M,11,0) -> 40 | F550: =VLOOKUP($A550,[1]彩含分析60315!$A:$M,12,0) -> 39 | G550: =VLOOKUP($A550,[1]彩含分析60315!$A:$M,13,0) -> 39 | H550: 调货 | I550: 90919-02098
A551: DQ4119A1 | B551: =VLOOKUP($A551,[1]彩含分析60315!$A:$M,8,0) -> 42 | C551: =VLOOKUP($A551,[1]彩含分析60315!$A:$M,9,0) -> 42 | D551: =VLOOKUP($A551,[1]彩含分析60315!$A:$M,10,0) -> 41 | E551: =VLOOKUP($A551,[1]彩含分析60315!$A:$M,11,0) -> 40 | F551: =VLOOKUP($A551,[1]彩含分析60315!$A:$M,12,0) -> 40 | G551: =VLOOKUP($A551,[1]彩含分析60315!$A:$M,13,0) -> 39 | H551: 调货 | I551: 马自达MX-3
A552: DQ4120A1 | B552: =VLOOKUP($A552,[1]彩含分析60315!$A:$M,8,0) -> 62 | C552: =VLOOKUP($A552,[1]彩含分析60315!$A:$M,9,0) -> 61 | D552: =VLOOKUP($A552,[1]彩含分析60315!$A:$M,10,0) -> 60 | E552: =VLOOKUP($A552,[1]彩含分析60315!$A:$M,11,0) -> 59 | F552: =VLOOKUP($A552,[1]彩含分析60315!$A:$M,12,0) -> 58 | G552: =VLOOKUP($A552,[1]彩含分析60315!$A:$M,13,0) -> 57 | H552: 调货 | I552: 雷克萨斯
A553: DQ4402A1 | B553: =VLOOKUP($A553,[1]彩含分析60315!$A:$M,8,0) -> 84 | C553: =VLOOKUP($A553,[1]彩含分析60315!$A:$M,9,0) -> 82 | D553: =VLOOKUP($A553,[1]彩含分析60315!$A:$M,10,0) -> 81 | E553: =VLOOKUP($A553,[1]彩含分析60315!$A:$M,11,0) -> 80 | F553: =VLOOKUP($A553,[1]彩含分析60315!$A:$M,12,0) -> 79 | G553: =VLOOKUP($A553,[1]彩含分析60315!$A:$M,13,0) -> 78 | H553: 调货 | I553: 起亚EIO L4
A554: DQ9003G7 | B554: =VLOOKUP($A554,[1]彩含分析60315!$A:$M,8,0) -> 49 | C554: =VLOOKUP($A554,[1]彩含分析60315!$A:$M,9,0) -> 48 | D554: =VLOOKUP($A554,[1]彩含分析60315!$A:$M,10,0) -> 47 | E554: =VLOOKUP($A554,[1]彩含分析60315!$A:$M,11,0) -> 47 | F554: =VLOOKUP($A554,[1]彩含分析60315!$A:$M,12,0) -> 46 | G554: =VLOOKUP($A554,[1]彩含分析60315!$A:$M,13,0) -> 45 | H554: 调货 | I554: 22448-6LBOA
A555: DQ9007K1 | B555: =VLOOKUP($A555,[1]彩含分析60315!$A:$M,8,0) -> 48 | C555: =VLOOKUP($A555,[1]彩含分析60315!$A:$M,9,0) -> 46 | D555: =VLOOKUP($A555,[1]彩含分析60315!$A:$M,10,0) -> 45 | E555: =VLOOKUP($A555,[1]彩含分析60315!$A:$M,11,0) -> 43 | F555: =VLOOKUP($A555,[1]彩含分析60315!$A:$M,12,0) -> 41 | G555: =VLOOKUP($A555,[1]彩含分析60315!$A:$M,13,0) -> 39 | H555: 自制 | I555: 现代起亚
A556: DQ9007M1 | B556: =VLOOKUP($A556,[1]彩含分析60315!$A:$M,8,0) -> 51 | C556: =VLOOKUP($A556,[1]彩含分析60315!$A:$M,9,0) -> 49 | D556: =VLOOKUP($A556,[1]彩含分析60315!$A:$M,10,0) -> 47 | E556: =VLOOKUP($A556,[1]彩含分析60315!$A:$M,11,0) -> 46 | F556: =VLOOKUP($A556,[1]彩含分析60315!$A:$M,12,0) -> 44 | G556: =VLOOKUP($A556,[1]彩含分析60315!$A:$M,13,0) -> 42 | H556: 自制 | I556: 现代伊兰特
A557: DQ9007Q1 | B557: =VLOOKUP($A557,[1]彩含分析60315!$A:$M,8,0) -> 49 | C557: =VLOOKUP($A557,[1]彩含分析60315!$A:$M,9,0) -> 48 | D557: =VLOOKUP($A557,[1]彩含分析60315!$A:$M,10,0) -> 46 | E557: =VLOOKUP($A557,[1]彩含分析60315!$A:$M,11,0) -> 44 | F557: =VLOOKUP($A557,[1]彩含分析60315!$A:$M,12,0) -> 42 | G557: =VLOOKUP($A557,[1]彩含分析60315!$A:$M,13,0) -> 40 | H557: 自制 | I557: 现代起亚
A558: DQ901872 | B558: =VLOOKUP($A558,[1]彩含分析60315!$A:$M,8,0) -> 60 | C558: =VLOOKUP($A558,[1]彩含分析60315!$A:$M,9,0) -> 59 | D558: =VLOOKUP($A558,[1]彩含分析60315!$A:$M,10,0) -> 58 | E558: =VLOOKUP($A558,[1]彩含分析60315!$A:$M,11,0) -> 57 | F558: =VLOOKUP($A558,[1]彩含分析60315!$A:$M,12,0) -> 56 | G558: =VLOOKUP($A558,[1]彩含分析60315!$A:$M,13,0) -> 55 | H558: 调货 | I558: 丰田02272
A559: DQ901877 | B559: =VLOOKUP($A559,[1]彩含分析60315!$A:$M,8,0) -> 50 | C559: =VLOOKUP($A559,[1]彩含分析60315!$A:$M,9,0) -> 49 | D559: =VLOOKUP($A559,[1]彩含分析60315!$A:$M,10,0) -> 47 | E559: =VLOOKUP($A559,[1]彩含分析60315!$A:$M,11,0) -> 45 | F559: =VLOOKUP($A559,[1]彩含分析60315!$A:$M,12,0) -> 43 | G559: =VLOOKUP($A559,[1]彩含分析60315!$A:$M,13,0) -> 41 | H559: 自制 | I559: 雷凌1.5L
A560: DQ9031E1 | B560: =VLOOKUP($A560,[1]彩含分析60315!$A:$M,8,0) -> 54 | C560: =VLOOKUP($A560,[1]彩含分析60315!$A:$M,9,0) -> 52 | D560: =VLOOKUP($A560,[1]彩含分析60315!$A:$M,10,0) -> 50 | E560: =VLOOKUP($A560,[1]彩含分析60315!$A:$M,11,0) -> 48 | F560: =VLOOKUP($A560,[1]彩含分析60315!$A:$M,12,0) -> 46 | G560: =VLOOKUP($A560,[1]彩含分析60315!$A:$M,13,0) -> 44 | H560: 自制 | I560: MG6 1.5T
...

Sheet 彩未价60319
A1: 对外型号 | B1: NP彩未60319 | C1: LP彩未60319 | D1: SLP彩未60319 | E1: 2S彩未60319 | F1: 3S彩未60319 | G1: 4S彩未60319 | H1: 属性 | I1: 通用名
A2: DQ910852 | B2: =VLOOKUP($A2,[1]彩未分析60315!$A:$M,8,0) -> 35 | C2: =VLOOKUP($A2,[1]彩未分析60315!$A:$M,9,0) -> 34 | D2: =VLOOKUP($A2,[1]彩未分析60315!$A:$M,10,0) -> 32 | E2: =VLOOKUP($A2,[1]彩未分析60315!$A:$M,11,0) -> 31 | F2: =VLOOKUP($A2,[1]彩未分析60315!$A:$M,12,0) -> 30 | G2: =VLOOKUP($A2,[1]彩未分析60315!$A:$M,13,0) -> 29 | H2: 自制 | I2: 丰田卡罗拉
A3: DQ9101B1 | B3: =VLOOKUP($A3,[1]彩未分析60315!$A:$M,8,0) -> 22 | C3: =VLOOKUP($A3,[1]彩未分析60315!$A:$M,9,0) -> 21 | D3: =VLOOKUP($A3,[1]彩未分析60315!$A:$M,10,0) -> 20 | E3: =VLOOKUP($A3,[1]彩未分析60315!$A:$M,11,0) -> 19 | F3: =VLOOKUP($A3,[1]彩未分析60315!$A:$M,12,0) -> 19 | G3: =VLOOKUP($A3,[1]彩未分析60315!$A:$M,13,0) -> 18 | H3: 自制 | I3: 伽玛发动机
A4: DQ9106L | B4: =VLOOKUP($A4,[1]彩未分析60315!$A:$M,8,0) -> 37 | C4: =VLOOKUP($A4,[1]彩未分析60315!$A:$M,9,0) -> 36 | D4: =VLOOKUP($A4,[1]彩未分析60315!$A:$M,10,0) -> 35 | E4: =VLOOKUP($A4,[1]彩未分析60315!$A:$M,11,0) -> 33 | F4: =VLOOKUP($A4,[1]彩未分析60315!$A:$M,12,0) -> 32 | G4: =VLOOKUP($A4,[1]彩未分析60315!$A:$M,13,0) -> 31 | H4: 自制 | I4: 波罗
A5: DQ9103A | B5: =VLOOKUP($A5,[1]彩未分析60315!$A:$M,8,0) -> 40 | C5: =VLOOKUP($A5,[1]彩未分析60315!$A:$M,9,0) -> 38 | D5: =VLOOKUP($A5,[1]彩未分析60315!$A:$M,10,0) -> 37 | E5: =VLOOKUP($A5,[1]彩未分析60315!$A:$M,11,0) -> 36 | F5: =VLOOKUP($A5,[1]彩未分析60315!$A:$M,12,0) -> 34 | G5: =VLOOKUP($A5,[1]彩未分析60315!$A:$M,13,0) -> 33 | H5: 自制 | I5: 奥迪C6
A6: DQ9101A | B6: =VLOOKUP($A6,[1]彩未分析60315!$A:$M,8,0) -> 22 | C6: =VLOOKUP($A6,[1]彩未分析60315!$A:$M,9,0) -> 21 | D6: =VLOOKUP($A6,[1]彩未分析60315!$A:$M,10,0) -> 20 | E6: =VLOOKUP($A6,[1]彩未分析60315!$A:$M,11,0) -> 20 | F6: =VLOOKUP($A6,[1]彩未分析60315!$A:$M,12,0) -> 19 | G6: =VLOOKUP($A6,[1]彩未分析60315!$A:$M,13,0) -> 18 | H6: 自制 | I6: 伊兰特 VVT 圆头
A7: DQ9115A | B7: =VLOOKUP($A7,[1]彩未分析60315!$A:$M,8,0) -> 23 | C7: =VLOOKUP($A7,[1]彩未分析60315!$A:$M,9,0) -> 22 | D7: =VLOOKUP($A7,[1]彩未分析60315!$A:$M,10,0) -> 21 | E7: =VLOOKUP($A7,[1]彩未分析60315!$A:$M,11,0) -> 20 | F7: =VLOOKUP($A7,[1]彩未分析60315!$A:$M,12,0) -> 20 | G7: =VLOOKUP($A7,[1]彩未分析60315!$A:$M,13,0) -> 19 | H7: 自制 | I7: 4A9
A8: DQ9012 | B8: =VLOOKUP($A8,[1]彩未分析60315!$A:$M,8,0) -> 40 | C8: =VLOOKUP($A8,[1]彩未分析60315!$A:$M,9,0) -> 38 | D8: =VLOOKUP($A8,[1]彩未分析60315!$A:$M,10,0) -> 37 | E8: =VLOOKUP($A8,[1]彩未分析60315!$A:$M,11,0) -> 36 | F8: =VLOOKUP($A8,[1]彩未分析60315!$A:$M,12,0) -> 34 | G8: =VLOOKUP($A8,[1]彩未分析60315!$A:$M,13,0) -> 33 | H8: 自制 | I8: 骐达
A9: DQ9219A | B9: =VLOOKUP($A9,[1]彩未分析60315!$A:$M,8,0) -> 27 | C9: =VLOOKUP($A9,[1]彩未分析60315!$A:$M,9,0) -> 26 | D9: =VLOOKUP($A9,[1]彩未分析60315!$A:$M,10,0) -> 25 | E9: =VLOOKUP($A9,[1]彩未分析60315!$A:$M,11,0) -> 24 | F9: =VLOOKUP($A9,[1]彩未分析60315!$A:$M,12,0) -> 23 | G9: =VLOOKUP($A9,[1]彩未分析60315!$A:$M,13,0) -> 22 | H9: 自制 | I9: 哈弗H6 1.5T
A10: DQ9103D | B10: =VLOOKUP($A10,[1]彩未分析60315!$A:$M,8,0) -> 39 | C10: =VLOOKUP($A10,[1]彩未分析60315!$A:$M,9,0) -> 38 | D10: =VLOOKUP($A10,[1]彩未分析60315!$A:$M,10,0) -> 37 | E10: =VLOOKUP($A10,[1]彩未分析60315!$A:$M,11,0) -> 35 | F10: =VLOOKUP($A10,[1]彩未分析60315!$A:$M,12,0) -> 34 | G10: =VLOOKUP($A10,[1]彩未分析60315!$A:$M,13,0) -> 32 | H10: 自制 | I10: 帕萨特B5 不铣胶面
A11: DQ910848 | B11: =VLOOKUP($A11,[1]彩未分析60315!$A:$M,8,0) -> 33 | C11: =VLOOKUP($A11,[1]彩未分析60315!$A:$M,9,0) -> 32 | D11: =VLOOKUP($A11,[1]彩未分析60315!$A:$M,10,0) -> 31 | E11: =VLOOKUP($A11,[1]彩未分析60315!$A:$M,11,0) -> 30 | F11: =VLOOKUP($A11,[1]彩未分析60315!$A:$M,12,0) -> 29 | G11: =VLOOKUP($A11,[1]彩未分析60315!$A:$M,13,0) -> 27 | H11: 自制 | I11: 丰田02248
A12: DQ9003H2 | B12: =VLOOKUP($A12,[1]彩未分析60315!$A:$M,8,0) -> 33 | C12: =VLOOKUP($A12,[1]彩未分析60315!$A:$M,9,0) -> 32 | D12: =VLOOKUP($A12,[1]彩未分析60315!$A:$M,10,0) -> 31 | E12: =VLOOKUP($A12,[1]彩未分析60315!$A:$M,11,0) -> 29 | F12: =VLOOKUP($A12,[1]彩未分析60315!$A:$M,12,0) -> 28 | G12: =VLOOKUP($A12,[1]彩未分析60315!$A:$M,13,0) -> 27 | H12: 自制 | I12: 尼桑
A13: DQ9401 | B13: =VLOOKUP($A13,[1]彩未分析60315!$A:$M,8,0) -> 39 | C13: =VLOOKUP($A13,[1]彩未分析60315!$A:$M,9,0) -> 38 | D13: =VLOOKUP($A13,[1]彩未分析60315!$A:$M,10,0) -> 37 | E13: =VLOOKUP($A13,[1]彩未分析60315!$A:$M,11,0) -> 35 | F13: =VLOOKUP($A13,[1]彩未分析60315!$A:$M,12,0) -> 34 | G13: =VLOOKUP($A13,[1]彩未分析60315!$A:$M,13,0) -> 32 | H13: 自制 | I13: 德尔福三代
... A473: DQ9003J2 | B473: =VLOOKUP($A473,[1]彩未分析60315!$A:$M,8,0) -> 45 | C473: =VLOOKUP($A473,[1]彩未分析60315!$A:$M,9,0) -> 43 | D473: =VLOOKUP($A473,[1]彩未分析60315!$A:$M,10,0) -> 41 | E473: =VLOOKUP($A473,[1]彩未分析60315!$A:$M,11,0) -> 40 | F473: =VLOOKUP($A473,[1]彩未分析60315!$A:$M,12,0) -> 38 | G473: =VLOOKUP($A473,[1]彩未分析60315!$A:$M,13,0) -> 37 | H473: 自制 | I473: 途乐4.0L
A474: DQ9003K1 | B474: =VLOOKUP($A474,[1]彩未分析60315!$A:$M,8,0) -> 52 | C474: =VLOOKUP($A474,[1]彩未分析60315!$A:$M,9,0) -> 52 | D474: =VLOOKUP($A474,[1]彩未分析60315!$A:$M,10,0) -> 51 | E474: =VLOOKUP($A474,[1]彩未分析60315!$A:$M,11,0) -> 50 | F474: =VLOOKUP($A474,[1]彩未分析60315!$A:$M,12,0) -> 49 | G474: =VLOOKUP($A474,[1]彩未分析60315!$A:$M,13,0) -> 49 | H474: 调货 | I474: 0
A475: DQ9004D2 | B475: =VLOOKUP($A475,[1]彩未分析60315!$A:$M,8,0) -> 38 | C475: =VLOOKUP($A475,[1]彩未分析60315!$A:$M,9,0) -> 37 | D475: =VLOOKUP($A475,[1]彩未分析60315!$A:$M,10,0) -> 36 | E475: =VLOOKUP($A475,[1]彩未分析60315!$A:$M,11,0) -> 34 | F475: =VLOOKUP($A475,[1]彩未分析60315!$A:$M,12,0) -> 33 | G475: =VLOOKUP($A475,[1]彩未分析60315!$A:$M,13,0) -> 31 | H475: 自制 | I475: 尼桑
A476: DQ9005M1 | B476: =VLOOKUP($A476,[1]彩未分析60315!$A:$M,8,0) -> 29 | C476: =VLOOKUP($A476,[1]彩未分析60315!$A:$M,9,0) -> 28 | D476: =VLOOKUP($A476,[1]彩未分析60315!$A:$M,10,0) -> 28 | E476: =VLOOKUP($A476,[1]彩未分析60315!$A:$M,11,0) -> 27 | F476: =VLOOKUP($A476,[1]彩未分析60315!$A:$M,12,0) -> 27 | G476: =VLOOKUP($A476,[1]彩未分析60315!$A:$M,13,0) -> 27 | H476: 调货 | I476: 福特96-99
A477: DQ9007J1 | B477: =VLOOKUP($A477,[1]彩未分析60315!$A:$M,8,0) -> 44 | C477: =VLOOKUP($A477,[1]彩未分析60315!$A:$M,9,0) -> 43 | D477: =VLOOKUP($A477,[1]彩未分析60315!$A:$M,10,0) -> 41 | E477: =VLOOKUP($A477,[1]彩未分析60315!$A:$M,11,0) -> 39 | F477: =VLOOKUP($A477,[1]彩未分析60315!$A:$M,12,0) -> 38 | G477: =VLOOKUP($A477,[1]彩未分析60315!$A:$M,13,0) -> 36 | H477: 自制 | I477: 现代3L030
A478: DQ9007H1 | B478: =VLOOKUP($A478,[1]彩未分析60315!$A:$M,8,0) -> 45 | C478: =VLOOKUP($A478,[1]彩未分析60315!$A:$M,9,0) -> 44 | D478: =VLOOKUP($A478,[1]彩未分析60315!$A:$M,10,0) -> 42 | E478: =VLOOKUP($A478,[1]彩未分析60315!$A:$M,11,0) -> 40 | F478: =VLOOKUP($A478,[1]彩未分析60315!$A:$M,12,0) -> 39 | G478: =VLOOKUP($A478,[1]彩未分析60315!$A:$M,13,0) -> 37 | H478: 自制 | I478: 2019 Kia Cadenza 3.3l
A479: DQ9008A1 | B479: =VLOOKUP($A479,[1]彩未分析60315!$A:$M,8,0) -> 45 | C479: =VLOOKUP($A479,[1]彩未分析60315!$A:$M,9,0) -> 45 | D479: =VLOOKUP($A479,[1]彩未分析60315!$A:$M,10,0) -> 44 | E479: =VLOOKUP($A479,[1]彩未分析60315!$A:$M,11,0) -> 43 | F479: =VLOOKUP($A479,[1]彩未分析60315!$A:$M,12,0) -> 43 | G479: =VLOOKUP($A479,[1]彩未分析60315!$A:$M,13,0) -> 42 | H479: 调货 | I479: 三菱蓝瑟4G93
A480: DQ9008B1 | B480: =VLOOKUP($A480,[1]彩未分析60315!$A:$M,8,0) -> 51 | C480: =VLOOKUP($A480,[1]彩未分析60315!$A:$M,9,0) -> 50 | D480: =VLOOKUP($A480,[1]彩未分析60315!$A:$M,10,0) -> 49 | E480: =VLOOKUP($A480,[1]彩未分析60315!$A:$M,11,0) -> 48 | F480: =VLOOKUP($A480,[1]彩未分析60315!$A:$M,12,0) -> 48 | G480: =VLOOKUP($A480,[1]彩未分析60315!$A:$M,13,0) -> 47 | H480: 调货 | I480: 三菱蓝瑟08-12 2.0L
A481: DQ9010G1 | B481: =VLOOKUP($A481,[1]彩未分析60315!$A:$M,8,0) -> 44 | C481: =VLOOKUP($A481,[1]彩未分析60315!$A:$M,9,0) -> 42 | D481: =VLOOKUP($A481,[1]彩未分析60315!$A:$M,10,0) -> 41 | E481: =VLOOKUP($A481,[1]彩未分析60315!$A:$M,11,0) -> 39 | F481: =VLOOKUP($A481,[1]彩未分析60315!$A:$M,12,0) -> 37 | G481: =VLOOKUP($A481,[1]彩未分析60315!$A:$M,13,0) -> 36 | H481: 自制 | I481: 本田锋范
A482: DQ9010L1 | B482: =VLOOKUP($A482,[1]彩未分析60315!$A:$M,8,0) -> 34 | C482: =VLOOKUP($A482,[1]彩未分析60315!$A:$M,9,0) -> 33 | D482: =VLOOKUP($A482,[1]彩未分析60315!$A:$M,10,0) -> 32 | E482: =VLOOKUP($A482,[1]彩未分析60315!$A:$M,11,0) -> 31 | F482: =VLOOKUP($A482,[1]彩未分析60315!$A:$M,12,0) -> 29 | G482: =VLOOKUP($A482,[1]彩未分析60315!$A:$M,13,0) -> 28 | H482: 自制 | I482: 本田飞度混动2013款
A483: DQ901810 | B483: =VLOOKUP($A483,[1]彩未分析60315!$A:$M,8,0) -> 56 | C483: =VLOOKUP($A483,[1]彩未分析60315!$A:$M,9,0) -> 55 | D483: =VLOOKUP($A483,[1]彩未分析60315!$A:$M,10,0) -> 54 | E483: =VLOOKUP($A483,[1]彩未分析60315!$A:$M,11,0) -> 53 | F483: =VLOOKUP($A483,[1]彩未分析60315!$A:$M,12,0) -> 53 | G483: =VLOOKUP($A483,[1]彩未分析60315!$A:$M,13,0) -> 52 | H483: 调货 | I483: 丰田2017-201818致炫
A484: DQ9024 | B484: =VLOOKUP($A484,[1]彩未分析60315!$A:$M,8,0) -> 74 | C484: =VLOOKUP($A484,[1]彩未分析60315!$A:$M,9,0) -> 73 | D484: =VLOOKUP($A484,[1]彩未分析60315!$A:$M,10,0) -> 71 | E484: =VLOOKUP($A484,[1]彩未分析60315!$A:$M,11,0) -> 70 | F484: =VLOOKUP($A484,[1]彩未分析60315!$A:$M,12,0) -> 70 | G484: =VLOOKUP($A484,[1]彩未分析60315!$A:$M,13,0) -> 68 | H484: 调货 | I484: 竞技 骑兵
A485: DQ9030C1 | B485: =VLOOKUP($A485,[1]彩未分析60315!$A:$M,8,0) -> 48 | C485: =VLOOKUP($A485,[1]彩未分析60315!$A:$M,9,0) -> 47 | D485: =VLOOKUP($A485,[1]彩未分析60315!$A:$M,10,0) -> 45 | E485: =VLOOKUP($A485,[1]彩未分析60315!$A:$M,11,0) -> 43 | F485: =VLOOKUP($A485,[1]彩未分析60315!$A:$M,12,0) -> 41 | G485: =VLOOKUP($A485,[1]彩未分析60315!$A:$M,13,0) -> 39 | H485: 自制 | I485: 长安福特 金牛座2.7T
A486: DQ9034A3 | B486: =VLOOKUP($A486,[1]彩未分析60315!$A:$M,8,0) -> 35 | C486: =VLOOKUP($A486,[1]彩未分析60315!$A:$M,9,0) -> 34 | D486: =VLOOKUP($A486,[1]彩未分析60315!$A:$M,10,0) -> 32 | E486: =VLOOKUP($A486,[1]彩未分析60315!$A:$M,11,0) -> 31 | F486: =VLOOKUP($A486,[1]彩未分析60315!$A:$M,12,0) -> 30 | G486: =VLOOKUP($A486,[1]彩未分析60315!$A:$M,13,0) -> 29 | H486: 自制 | I486: 纳智捷TT26S
... A548: DQ4202A1 | B548: =VLOOKUP($A548,[1]彩未分析60315!$A:$M,8,0) -> 60 | C548: =VLOOKUP($A548,[1]彩未分析60315!$A:$M,9,0) -> 59 | D548: =VLOOKUP($A548,[1]彩未分析60315!$A:$M,10,0) -> 58 | E548: =VLOOKUP($A548,[1]彩未分析60315!$A:$M,11,0) -> 57 | F548: =VLOOKUP($A548,[1]彩未分析60315!$A:$M,12,0) -> 57 | G548: =VLOOKUP($A548,[1]彩未分析60315!$A:$M,13,0) -> 56 | H548: 调货 | I548: 丰田SR40
A549: DQ4106A1 | B549: =VLOOKUP($A549,[1]彩未分析60315!$A:$M,8,0) -> 45 | C549: =VLOOKUP($A549,[1]彩未分析60315!$A:$M,9,0) -> 44 | D549: =VLOOKUP($A549,[1]彩未分析60315!$A:$M,10,0) -> 42 | E549: =VLOOKUP($A549,[1]彩未分析60315!$A:$M,11,0) -> 40 | F549: =VLOOKUP($A549,[1]彩未分析60315!$A:$M,12,0) -> 39 | G549: =VLOOKUP($A549,[1]彩未分析60315!$A:$M,13,0) -> 37 | H549: 自制 | I549: 12713668
A550: DQ4115A1 | B550: =VLOOKUP($A550,[1]彩未分析60315!$A:$M,8,0) -> 40 | C550: =VLOOKUP($A550,[1]彩未分析60315!$A:$M,9,0) -> 39 | D550: =VLOOKUP($A550,[1]彩未分析60315!$A:$M,10,0) -> 38 | E550: =VLOOKUP($A550,[1]彩未分析60315!$A:$M,11,0) -> 38 | F550: =VLOOKUP($A550,[1]彩未分析60315!$A:$M,12,0) -> 37 | G550: =VLOOKUP($A550,[1]彩未分析60315!$A:$M,13,0) -> 37 | H550: 调货 | I550: 90919-02098
A551: DQ4119A1 | B551: =VLOOKUP($A551,[1]彩未分析60315!$A:$M,8,0) -> 40 | C551: =VLOOKUP($A551,[1]彩未分析60315!$A:$M,9,0) -> 40 | D551: =VLOOKUP($A551,[1]彩未分析60315!$A:$M,10,0) -> 39 | E551: =VLOOKUP($A551,[1]彩未分析60315!$A:$M,11,0) -> 38 | F551: =VLOOKUP($A551,[1]彩未分析60315!$A:$M,12,0) -> 38 | G551: =VLOOKUP($A551,[1]彩未分析60315!$A:$M,13,0) -> 37 | H551: 调货 | I551: 马自达MX-3
A552: DQ4120A1 | B552: =VLOOKUP($A552,[1]彩未分析60315!$A:$M,8,0) -> 59 | C552: =VLOOKUP($A552,[1]彩未分析60315!$A:$M,9,0) -> 58 | D552: =VLOOKUP($A552,[1]彩未分析60315!$A:$M,10,0) -> 57 | E552: =VLOOKUP($A552,[1]彩未分析60315!$A:$M,11,0) -> 56 | F552: =VLOOKUP($A552,[1]彩未分析60315!$A:$M,12,0) -> 56 | G552: =VLOOKUP($A552,[1]彩未分析60315!$A:$M,13,0) -> 55 | H552: 调货 | I552: 雷克萨斯
A553: DQ4402A1 | B553: =VLOOKUP($A553,[1]彩未分析60315!$A:$M,8,0) -> 80 | C553: =VLOOKUP($A553,[1]彩未分析60315!$A:$M,9,0) -> 79 | D553: =VLOOKUP($A553,[1]彩未分析60315!$A:$M,10,0) -> 77 | E553: =VLOOKUP($A553,[1]彩未分析60315!$A:$M,11,0) -> 76 | F553: =VLOOKUP($A553,[1]彩未分析60315!$A:$M,12,0) -> 75 | G553: =VLOOKUP($A553,[1]彩未分析60315!$A:$M,13,0) -> 74 | H553: 调货 | I553: 起亚EIO L4
A554: DQ9003G7 | B554: =VLOOKUP($A554,[1]彩未分析60315!$A:$M,8,0) -> 47 | C554: =VLOOKUP($A554,[1]彩未分析60315!$A:$M,9,0) -> 46 | D554: =VLOOKUP($A554,[1]彩未分析60315!$A:$M,10,0) -> 45 | E554: =VLOOKUP($A554,[1]彩未分析60315!$A:$M,11,0) -> 44 | F554: =VLOOKUP($A554,[1]彩未分析60315!$A:$M,12,0) -> 44 | G554: =VLOOKUP($A554,[1]彩未分析60315!$A:$M,13,0) -> 43 | H554: 调货 | I554: 22448-6LBOA
A555: DQ9007K1 | B555: =VLOOKUP($A555,[1]彩未分析60315!$A:$M,8,0) -> 45 | C555: =VLOOKUP($A555,[1]彩未分析60315!$A:$M,9,0) -> 43 | D555: =VLOOKUP($A555,[1]彩未分析60315!$A:$M,10,0) -> 42 | E555: =VLOOKUP($A555,[1]彩未分析60315!$A:$M,11,0) -> 40 | F555: =VLOOKUP($A555,[1]彩未分析60315!$A:$M,12,0) -> 38 | G555: =VLOOKUP($A555,[1]彩未分析60315!$A:$M,13,0) -> 37 | H555: 自制 | I555: 现代起亚
A556: DQ9007M1 | B556: =VLOOKUP($A556,[1]彩未分析60315!$A:$M,8,0) -> 48 | C556: =VLOOKUP($A556,[1]彩未分析60315!$A:$M,9,0) -> 46 | D556: =VLOOKUP($A556,[1]彩未分析60315!$A:$M,10,0) -> 44 | E556: =VLOOKUP($A556,[1]彩未分析60315!$A:$M,11,0) -> 42 | F556: =VLOOKUP($A556,[1]彩未分析60315!$A:$M,12,0) -> 41 | G556: =VLOOKUP($A556,[1]彩未分析60315!$A:$M,13,0) -> 39 | H556: 自制 | I556: 现代伊兰特
A557: DQ9007Q1 | B557: =VLOOKUP($A557,[1]彩未分析60315!$A:$M,8,0) -> 47 | C557: =VLOOKUP($A557,[1]彩未分析60315!$A:$M,9,0) -> 45 | D557: =VLOOKUP($A557,[1]彩未分析60315!$A:$M,10,0) -> 43 | E557: =VLOOKUP($A557,[1]彩未分析60315!$A:$M,11,0) -> 42 | F557: =VLOOKUP($A557,[1]彩未分析60315!$A:$M,12,0) -> 40 | G557: =VLOOKUP($A557,[1]彩未分析60315!$A:$M,13,0) -> 38 | H557: 自制 | I557: 现代起亚
A558: DQ901872 | B558: =VLOOKUP($A558,[1]彩未分析60315!$A:$M,8,0) -> 57 | C558: =VLOOKUP($A558,[1]彩未分析60315!$A:$M,9,0) -> 56 | D558: =VLOOKUP($A558,[1]彩未分析60315!$A:$M,10,0) -> 55 | E558: =VLOOKUP($A558,[1]彩未分析60315!$A:$M,11,0) -> 54 | F558: =VLOOKUP($A558,[1]彩未分析60315!$A:$M,12,0) -> 54 | G558: =VLOOKUP($A558,[1]彩未分析60315!$A:$M,13,0) -> 53 | H558: 调货 | I558: 丰田02272
A559: DQ901877 | B559: =VLOOKUP($A559,[1]彩未分析60315!$A:$M,8,0) -> 47 | C559: =VLOOKUP($A559,[1]彩未分析60315!$A:$M,9,0) -> 45 | D559: =VLOOKUP($A559,[1]彩未分析60315!$A:$M,10,0) -> 43 | E559: =VLOOKUP($A559,[1]彩未分析60315!$A:$M,11,0) -> 42 | F559: =VLOOKUP($A559,[1]彩未分析60315!$A:$M,12,0) -> 40 | G559: =VLOOKUP($A559,[1]彩未分析60315!$A:$M,13,0) -> 38 | H559: 自制 | I559: 雷凌1.5L
A560: DQ9031E1 | B560: =VLOOKUP($A560,[1]彩未分析60315!$A:$M,8,0) -> 51 | C560: =VLOOKUP($A560,[1]彩未分析60315!$A:$M,9,0) -> 49 | D560: =VLOOKUP($A560,[1]彩未分析60315!$A:$M,10,0) -> 47 | E560: =VLOOKUP($A560,[1]彩未分析60315!$A:$M,11,0) -> 45 | F560: =VLOOKUP($A560,[1]彩未分析60315!$A:$M,12,0) -> 43 | G560: =VLOOKUP($A560,[1]彩未分析60315!$A:$M,13,0) -> 41 | H560: 自制 | I560: MG6 1.5T
...

Sheet 中含价60319
A1: 对外型号 | B1: NP中含60319 | C1: LP中含60319 | D1: SLP中含60319 | E1: 2S中含60319 | F1: 3S中含60319 | G1: 4S中含60319 | H1: 属性 | I1: 通用名
A2: DQ910852 | B2: =VLOOKUP($A2,[1]中含分析60315!$A:$M,8,0) -> 37 | C2: =VLOOKUP($A2,[1]中含分析60315!$A:$M,9,0) -> 36 | D2: =VLOOKUP($A2,[1]中含分析60315!$A:$M,10,0) -> 34 | E2: =VLOOKUP($A2,[1]中含分析60315!$A:$M,11,0) -> 33 | F2: =VLOOKUP($A2,[1]中含分析60315!$A:$M,12,0) -> 31 | G2: =VLOOKUP($A2,[1]中含分析60315!$A:$M,13,0) -> 30 | H2: 自制 | I2: 丰田卡罗拉
A3: DQ9101B1 | B3: =VLOOKUP($A3,[1]中含分析60315!$A:$M,8,0) -> 23 | C3: =VLOOKUP($A3,[1]中含分析60315!$A:$M,9,0) -> 22 | D3: =VLOOKUP($A3,[1]中含分析60315!$A:$M,10,0) -> 21 | E3: =VLOOKUP($A3,[1]中含分析60315!$A:$M,11,0) -> 21 | F3: =VLOOKUP($A3,[1]中含分析60315!$A:$M,12,0) -> 20 | G3: =VLOOKUP($A3,[1]中含分析60315!$A:$M,13,0) -> 19 | H3: 自制 | I3: 伽玛发动机
A4: DQ9106L | B4: =VLOOKUP($A4,[1]中含分析60315!$A:$M,8,0) -> 40 | C4: =VLOOKUP($A4,[1]中含分析60315!$A:$M,9,0) -> 38 | D4: =VLOOKUP($A4,[1]中含分析60315!$A:$M,10,0) -> 37 | E4: =VLOOKUP($A4,[1]中含分析60315!$A:$M,11,0) -> 35 | F4: =VLOOKUP($A4,[1]中含分析60315!$A:$M,12,0) -> 34 | G4: =VLOOKUP($A4,[1]中含分析60315!$A:$M,13,0) -> 32 | H4: 自制 | I4: 波罗
A5: DQ9103A | B5: =VLOOKUP($A5,[1]中含分析60315!$A:$M,8,0) -> 42 | C5: =VLOOKUP($A5,[1]中含分析60315!$A:$M,9,0) -> 41 | D5: =VLOOKUP($A5,[1]中含分析60315!$A:$M,10,0) -> 39 | E5: =VLOOKUP($A5,[1]中含分析60315!$A:$M,11,0) -> 38 | F5: =VLOOKUP($A5,[1]中含分析60315!$A:$M,12,0) -> 36 | G5: =VLOOKUP($A5,[1]中含分析60315!$A:$M,13,0) -> 35 | H5: 自制 | I5: 奥迪C6
A6: DQ9101A | B6: =VLOOKUP($A6,[1]中含分析60315!$A:$M,8,0) -> 23 | C6: =VLOOKUP($A6,[1]中含分析60315!$A:$M,9,0) -> 22 | D6: =VLOOKUP($A6,[1]中含分析60315!$A:$M,10,0) -> 21 | E6: =VLOOKUP($A6,[1]中含分析60315!$A:$M,11,0) -> 21 | F6: =VLOOKUP($A6,[1]中含分析60315!$A:$M,12,0) -> 20 | G6: =VLOOKUP($A6,[1]中含分析60315!$A:$M,13,0) -> 19 | H6: 自制 | I6: 伊兰特 VVT 圆头
A7: DQ9115A | B7: =VLOOKUP($A7,[1]中含分析60315!$A:$M,8,0) -> 25 | C7: =VLOOKUP($A7,[1]中含分析60315!$A:$M,9,0) -> 24 | D7: =VLOOKUP($A7,[1]中含分析60315!$A:$M,10,0) -> 23 | E7: =VLOOKUP($A7,[1]中含分析60315!$A:$M,11,0) -> 22 | F7: =VLOOKUP($A7,[1]中含分析60315!$A:$M,12,0) -> 21 | G7: =VLOOKUP($A7,[1]中含分析60315!$A:$M,13,0) -> 20 | H7: 自制 | I7: 4A9
A8: DQ9012 | B8: =VLOOKUP($A8,[1]中含分析60315!$A:$M,8,0) -> 42 | C8: =VLOOKUP($A8,[1]中含分析60315!$A:$M,9,0) -> 41 | D8: =VLOOKUP($A8,[1]中含分析60315!$A:$M,10,0) -> 39 | E8: =VLOOKUP($A8,[1]中含分析60315!$A:$M,11,0) -> 38 | F8: =VLOOKUP($A8,[1]中含分析60315!$A:$M,12,0) -> 36 | G8: =VLOOKUP($A8,[1]中含分析60315!$A:$M,13,0) -> 35 | H8: 自制 | I8: 骐达
A9: DQ9219A | B9: =VLOOKUP($A9,[1]中含分析60315!$A:$M,8,0) -> 29 | C9: =VLOOKUP($A9,[1]中含分析60315!$A:$M,9,0) -> 28 | D9: =VLOOKUP($A9,[1]中含分析60315!$A:$M,10,0) -> 27 | E9: =VLOOKUP($A9,[1]中含分析60315!$A:$M,11,0) -> 26 | F9: =VLOOKUP($A9,[1]中含分析60315!$A:$M,12,0) -> 24 | G9: =VLOOKUP($A9,[1]中含分析60315!$A:$M,13,0) -> 23 | H9: 自制 | I9: 哈弗H6 1.5T
A10: DQ9103D | B10: =VLOOKUP($A10,[1]中含分析60315!$A:$M,8,0) -> 42 | C10: =VLOOKUP($A10,[1]中含分析60315!$A:$M,9,0) -> 40 | D10: =VLOOKUP($A10,[1]中含分析60315!$A:$M,10,0) -> 39 | E10: =VLOOKUP($A10,[1]中含分析60315!$A:$M,11,0) -> 37 | F10: =VLOOKUP($A10,[1]中含分析60315!$A:$M,12,0) -> 36 | G10: =VLOOKUP($A10,[1]中含分析60315!$A:$M,13,0) -> 34 | H10: 自制 | I10: 帕萨特B5 不铣胶面
A11: DQ910848 | B11: =VLOOKUP($A11,[1]中含分析60315!$A:$M,8,0) -> 35 | C11: =VLOOKUP($A11,[1]中含分析60315!$A:$M,9,0) -> 34 | D11: =VLOOKUP($A11,[1]中含分析60315!$A:$M,10,0) -> 33 | E11: =VLOOKUP($A11,[1]中含分析60315!$A:$M,11,0) -> 31 | F11: =VLOOKUP($A11,[1]中含分析60315!$A:$M,12,0) -> 30 | G11: =VLOOKUP($A11,[1]中含分析60315!$A:$M,13,0) -> 29 | H11: 自制 | I11: 丰田02248
A12: DQ9003H2 | B12: =VLOOKUP($A12,[1]中含分析60315!$A:$M,8,0) -> 35 | C12: =VLOOKUP($A12,[1]中含分析60315!$A:$M,9,0) -> 34 | D12: =VLOOKUP($A12,[1]中含分析60315!$A:$M,10,0) -> 33 | E12: =VLOOKUP($A12,[1]中含分析60315!$A:$M,11,0) -> 31 | F12: =VLOOKUP($A12,[1]中含分析60315!$A:$M,12,0) -> 30 | G12: =VLOOKUP($A12,[1]中含分析60315!$A:$M,13,0) -> 29 | H12: 自制 | I12: 尼桑
A13: DQ9401 | B13: =VLOOKUP($A13,[1]中含分析60315!$A:$M,8,0) -> 42 | C13: =VLOOKUP($A13,[1]中含分析60315!$A:$M,9,0) -> 41 | D13: =VLOOKUP($A13,[1]中含分析60315!$A:$M,10,0) -> 39 | E13: =VLOOKUP($A13,[1]中含分析60315!$A:$M,11,0) -> 37 | F13: =VLOOKUP($A13,[1]中含分析60315!$A:$M,12,0) -> 36 | G13: =VLOOKUP($A13,[1]中含分析60315!$A:$M,13,0) -> 34 | H13: 自制 | I13: 德尔福三代
... A473: DQ9003J2 | B473: =VLOOKUP($A473,[1]中含分析60315!$A:$M,8,0) -> 47 | C473: =VLOOKUP($A473,[1]中含分析60315!$A:$M,9,0) -> 45 | D473: =VLOOKUP($A473,[1]中含分析60315!$A:$M,10,0) -> 44 | E473: =VLOOKUP($A473,[1]中含分析60315!$A:$M,11,0) -> 42 | F473: =VLOOKUP($A473,[1]中含分析60315!$A:$M,12,0) -> 40 | G473: =VLOOKUP($A473,[1]中含分析60315!$A:$M,13,0) -> 39 | H473: 自制 | I473: 途乐4.0L
A474: DQ9003K1 | B474: =VLOOKUP($A474,[1]中含分析60315!$A:$M,8,0) -> 55 | C474: =VLOOKUP($A474,[1]中含分析60315!$A:$M,9,0) -> 54 | D474: =VLOOKUP($A474,[1]中含分析60315!$A:$M,10,0) -> 53 | E474: =VLOOKUP($A474,[1]中含分析60315!$A:$M,11,0) -> 52 | F474: =VLOOKUP($A474,[1]中含分析60315!$A:$M,12,0) -> 52 | G474: =VLOOKUP($A474,[1]中含分析60315!$A:$M,13,0) -> 51 | H474: 调货 | I474: 0
A475: DQ9004D2 | B475: =VLOOKUP($A475,[1]中含分析60315!$A:$M,8,0) -> 41 | C475: =VLOOKUP($A475,[1]中含分析60315!$A:$M,9,0) -> 39 | D475: =VLOOKUP($A475,[1]中含分析60315!$A:$M,10,0) -> 38 | E475: =VLOOKUP($A475,[1]中含分析60315!$A:$M,11,0) -> 36 | F475: =VLOOKUP($A475,[1]中含分析60315!$A:$M,12,0) -> 35 | G475: =VLOOKUP($A475,[1]中含分析60315!$A:$M,13,0) -> 33 | H475: 自制 | I475: 尼桑
A476: DQ9005M1 | B476: =VLOOKUP($A476,[1]中含分析60315!$A:$M,8,0) -> 30 | C476: =VLOOKUP($A476,[1]中含分析60315!$A:$M,9,0) -> 30 | D476: =VLOOKUP($A476,[1]中含分析60315!$A:$M,10,0) -> 29 | E476: =VLOOKUP($A476,[1]中含分析60315!$A:$M,11,0) -> 29 | F476: =VLOOKUP($A476,[1]中含分析60315!$A:$M,12,0) -> 28 | G476: =VLOOKUP($A476,[1]中含分析60315!$A:$M,13,0) -> 28 | H476: 调货 | I476: 福特96-99
A477: DQ9007J1 | B477: =VLOOKUP($A477,[1]中含分析60315!$A:$M,8,0) -> 47 | C477: =VLOOKUP($A477,[1]中含分析60315!$A:$M,9,0) -> 45 | D477: =VLOOKUP($A477,[1]中含分析60315!$A:$M,10,0) -> 44 | E477: =VLOOKUP($A477,[1]中含分析60315!$A:$M,11,0) -> 42 | F477: =VLOOKUP($A477,[1]中含分析60315!$A:$M,12,0) -> 40 | G477: =VLOOKUP($A477,[1]中含分析60315!$A:$M,13,0) -> 38 | H477: 自制 | I477: 现代3L030
A478: DQ9007H1 | B478: =VLOOKUP($A478,[1]中含分析60315!$A:$M,8,0) -> 48 | C478: =VLOOKUP($A478,[1]中含分析60315!$A:$M,9,0) -> 46 | D478: =VLOOKUP($A478,[1]中含分析60315!$A:$M,10,0) -> 45 | E478: =VLOOKUP($A478,[1]中含分析60315!$A:$M,11,0) -> 43 | F478: =VLOOKUP($A478,[1]中含分析60315!$A:$M,12,0) -> 41 | G478: =VLOOKUP($A478,[1]中含分析60315!$A:$M,13,0) -> 39 | H478: 自制 | I478: 2019 Kia Cadenza 3.3l
A479: DQ9008A1 | B479: =VLOOKUP($A479,[1]中含分析60315!$A:$M,8,0) -> 48 | C479: =VLOOKUP($A479,[1]中含分析60315!$A:$M,9,0) -> 47 | D479: =VLOOKUP($A479,[1]中含分析60315!$A:$M,10,0) -> 46 | E479: =VLOOKUP($A479,[1]中含分析60315!$A:$M,11,0) -> 45 | F479: =VLOOKUP($A479,[1]中含分析60315!$A:$M,12,0) -> 45 | G479: =VLOOKUP($A479,[1]中含分析60315!$A:$M,13,0) -> 44 | H479: 调货 | I479: 三菱蓝瑟4G93
A480: DQ9008B1 | B480: =VLOOKUP($A480,[1]中含分析60315!$A:$M,8,0) -> 54 | C480: =VLOOKUP($A480,[1]中含分析60315!$A:$M,9,0) -> 53 | D480: =VLOOKUP($A480,[1]中含分析60315!$A:$M,10,0) -> 52 | E480: =VLOOKUP($A480,[1]中含分析60315!$A:$M,11,0) -> 51 | F480: =VLOOKUP($A480,[1]中含分析60315!$A:$M,12,0) -> 50 | G480: =VLOOKUP($A480,[1]中含分析60315!$A:$M,13,0) -> 49 | H480: 调货 | I480: 三菱蓝瑟08-12 2.0L
A481: DQ9010G1 | B481: =VLOOKUP($A481,[1]中含分析60315!$A:$M,8,0) -> 46 | C481: =VLOOKUP($A481,[1]中含分析60315!$A:$M,9,0) -> 45 | D481: =VLOOKUP($A481,[1]中含分析60315!$A:$M,10,0) -> 43 | E481: =VLOOKUP($A481,[1]中含分析60315!$A:$M,11,0) -> 41 | F481: =VLOOKUP($A481,[1]中含分析60315!$A:$M,12,0) -> 39 | G481: =VLOOKUP($A481,[1]中含分析60315!$A:$M,13,0) -> 38 | H481: 自制 | I481: 本田锋范
A482: DQ9010L1 | B482: =VLOOKUP($A482,[1]中含分析60315!$A:$M,8,0) -> 36 | C482: =VLOOKUP($A482,[1]中含分析60315!$A:$M,9,0) -> 35 | D482: =VLOOKUP($A482,[1]中含分析60315!$A:$M,10,0) -> 34 | E482: =VLOOKUP($A482,[1]中含分析60315!$A:$M,11,0) -> 32 | F482: =VLOOKUP($A482,[1]中含分析60315!$A:$M,12,0) -> 31 | G482: =VLOOKUP($A482,[1]中含分析60315!$A:$M,13,0) -> 30 | H482: 自制 | I482: 本田飞度混动2013款
A483: DQ901810 | B483: =VLOOKUP($A483,[1]中含分析60315!$A:$M,8,0) -> 59 | C483: =VLOOKUP($A483,[1]中含分析60315!$A:$M,9,0) -> 58 | D483: =VLOOKUP($A483,[1]中含分析60315!$A:$M,10,0) -> 57 | E483: =VLOOKUP($A483,[1]中含分析60315!$A:$M,11,0) -> 56 | F483: =VLOOKUP($A483,[1]中含分析60315!$A:$M,12,0) -> 56 | G483: =VLOOKUP($A483,[1]中含分析60315!$A:$M,13,0) -> 55 | H483: 调货 | I483: 丰田2017-201818致炫
A484: DQ9024 | B484: =VLOOKUP($A484,[1]中含分析60315!$A:$M,8,0) -> 78 | C484: =VLOOKUP($A484,[1]中含分析60315!$A:$M,9,0) -> 76 | D484: =VLOOKUP($A484,[1]中含分析60315!$A:$M,10,0) -> 75 | E484: =VLOOKUP($A484,[1]中含分析60315!$A:$M,11,0) -> 74 | F484: =VLOOKUP($A484,[1]中含分析60315!$A:$M,12,0) -> 73 | G484: =VLOOKUP($A484,[1]中含分析60315!$A:$M,13,0) -> 72 | H484: 调货 | I484: 竞技 骑兵
A485: DQ9030C1 | B485: =VLOOKUP($A485,[1]中含分析60315!$A:$M,8,0) -> 52 | C485: =VLOOKUP($A485,[1]中含分析60315!$A:$M,9,0) -> 50 | D485: =VLOOKUP($A485,[1]中含分析60315!$A:$M,10,0) -> 48 | E485: =VLOOKUP($A485,[1]中含分析60315!$A:$M,11,0) -> 46 | F485: =VLOOKUP($A485,[1]中含分析60315!$A:$M,12,0) -> 44 | G485: =VLOOKUP($A485,[1]中含分析60315!$A:$M,13,0) -> 42 | H485: 自制 | I485: 长安福特 金牛座2.7T
A486: DQ9034A3 | B486: =VLOOKUP($A486,[1]中含分析60315!$A:$M,8,0) -> 37 | C486: =VLOOKUP($A486,[1]中含分析60315!$A:$M,9,0) -> 36 | D486: =VLOOKUP($A486,[1]中含分析60315!$A:$M,10,0) -> 35 | E486: =VLOOKUP($A486,[1]中含分析60315!$A:$M,11,0) -> 33 | F486: =VLOOKUP($A486,[1]中含分析60315!$A:$M,12,0) -> 32 | G486: =VLOOKUP($A486,[1]中含分析60315!$A:$M,13,0) -> 31 | H486: 自制 | I486: 纳智捷TT26S
... A548: DQ4202A1 | B548: =VLOOKUP($A548,[1]中含分析60315!$A:$M,8,0) -> 63 | C548: =VLOOKUP($A548,[1]中含分析60315!$A:$M,9,0) -> 62 | D548: =VLOOKUP($A548,[1]中含分析60315!$A:$M,10,0) -> 61 | E548: =VLOOKUP($A548,[1]中含分析60315!$A:$M,11,0) -> 60 | F548: =VLOOKUP($A548,[1]中含分析60315!$A:$M,12,0) -> 59 | G548: =VLOOKUP($A548,[1]中含分析60315!$A:$M,13,0) -> 58 | H548: 调货 | I548: 丰田SR40
A549: DQ4106A1 | B549: =VLOOKUP($A549,[1]中含分析60315!$A:$M,8,0) -> 47 | C549: =VLOOKUP($A549,[1]中含分析60315!$A:$M,9,0) -> 46 | D549: =VLOOKUP($A549,[1]中含分析60315!$A:$M,10,0) -> 44 | E549: =VLOOKUP($A549,[1]中含分析60315!$A:$M,11,0) -> 42 | F549: =VLOOKUP($A549,[1]中含分析60315!$A:$M,12,0) -> 40 | G549: =VLOOKUP($A549,[1]中含分析60315!$A:$M,13,0) -> 39 | H549: 自制 | I549: 12713668
A550: DQ4115A1 | B550: =VLOOKUP($A550,[1]中含分析60315!$A:$M,8,0) -> 41 | C550: =VLOOKUP($A550,[1]中含分析60315!$A:$M,9,0) -> 41 | D550: =VLOOKUP($A550,[1]中含分析60315!$A:$M,10,0) -> 40 | E550: =VLOOKUP($A550,[1]中含分析60315!$A:$M,11,0) -> 39 | F550: =VLOOKUP($A550,[1]中含分析60315!$A:$M,12,0) -> 39 | G550: =VLOOKUP($A550,[1]中含分析60315!$A:$M,13,0) -> 38 | H550: 调货 | I550: 90919-02098
A551: DQ4119A1 | B551: =VLOOKUP($A551,[1]中含分析60315!$A:$M,8,0) -> 42 | C551: =VLOOKUP($A551,[1]中含分析60315!$A:$M,9,0) -> 41 | D551: =VLOOKUP($A551,[1]中含分析60315!$A:$M,10,0) -> 40 | E551: =VLOOKUP($A551,[1]中含分析60315!$A:$M,11,0) -> 40 | F551: =VLOOKUP($A551,[1]中含分析60315!$A:$M,12,0) -> 39 | G551: =VLOOKUP($A551,[1]中含分析60315!$A:$M,13,0) -> 39 | H551: 调货 | I551: 马自达MX-3
A552: DQ4120A1 | B552: =VLOOKUP($A552,[1]中含分析60315!$A:$M,8,0) -> 62 | C552: =VLOOKUP($A552,[1]中含分析60315!$A:$M,9,0) -> 61 | D552: =VLOOKUP($A552,[1]中含分析60315!$A:$M,10,0) -> 59 | E552: =VLOOKUP($A552,[1]中含分析60315!$A:$M,11,0) -> 58 | F552: =VLOOKUP($A552,[1]中含分析60315!$A:$M,12,0) -> 58 | G552: =VLOOKUP($A552,[1]中含分析60315!$A:$M,13,0) -> 57 | H552: 调货 | I552: 雷克萨斯
A553: DQ4402A1 | B553: =VLOOKUP($A553,[1]中含分析60315!$A:$M,8,0) -> 83 | C553: =VLOOKUP($A553,[1]中含分析60315!$A:$M,9,0) -> 82 | D553: =VLOOKUP($A553,[1]中含分析60315!$A:$M,10,0) -> 80 | E553: =VLOOKUP($A553,[1]中含分析60315!$A:$M,11,0) -> 79 | F553: =VLOOKUP($A553,[1]中含分析60315!$A:$M,12,0) -> 78 | G553: =VLOOKUP($A553,[1]中含分析60315!$A:$M,13,0) -> 77 | H553: 调货 | I553: 起亚EIO L4
A554: DQ9003G7 | B554: =VLOOKUP($A554,[1]中含分析60315!$A:$M,8,0) -> 49 | C554: =VLOOKUP($A554,[1]中含分析60315!$A:$M,9,0) -> 48 | D554: =VLOOKUP($A554,[1]中含分析60315!$A:$M,10,0) -> 47 | E554: =VLOOKUP($A554,[1]中含分析60315!$A:$M,11,0) -> 46 | F554: =VLOOKUP($A554,[1]中含分析60315!$A:$M,12,0) -> 46 | G554: =VLOOKUP($A554,[1]中含分析60315!$A:$M,13,0) -> 45 | H554: 调货 | I554: 22448-6LBOA
A555: DQ9007K1 | B555: =VLOOKUP($A555,[1]中含分析60315!$A:$M,8,0) -> 48 | C555: =VLOOKUP($A555,[1]中含分析60315!$A:$M,9,0) -> 46 | D555: =VLOOKUP($A555,[1]中含分析60315!$A:$M,10,0) -> 44 | E555: =VLOOKUP($A555,[1]中含分析60315!$A:$M,11,0) -> 43 | F555: =VLOOKUP($A555,[1]中含分析60315!$A:$M,12,0) -> 41 | G555: =VLOOKUP($A555,[1]中含分析60315!$A:$M,13,0) -> 39 | H555: 自制 | I555: 现代起亚
A556: DQ9007M1 | B556: =VLOOKUP($A556,[1]中含分析60315!$A:$M,8,0) -> 51 | C556: =VLOOKUP($A556,[1]中含分析60315!$A:$M,9,0) -> 49 | D556: =VLOOKUP($A556,[1]中含分析60315!$A:$M,10,0) -> 47 | E556: =VLOOKUP($A556,[1]中含分析60315!$A:$M,11,0) -> 45 | F556: =VLOOKUP($A556,[1]中含分析60315!$A:$M,12,0) -> 43 | G556: =VLOOKUP($A556,[1]中含分析60315!$A:$M,13,0) -> 42 | H556: 自制 | I556: 现代伊兰特
A557: DQ9007Q1 | B557: =VLOOKUP($A557,[1]中含分析60315!$A:$M,8,0) -> 49 | C557: =VLOOKUP($A557,[1]中含分析60315!$A:$M,9,0) -> 47 | D557: =VLOOKUP($A557,[1]中含分析60315!$A:$M,10,0) -> 45 | E557: =VLOOKUP($A557,[1]中含分析60315!$A:$M,11,0) -> 44 | F557: =VLOOKUP($A557,[1]中含分析60315!$A:$M,12,0) -> 42 | G557: =VLOOKUP($A557,[1]中含分析60315!$A:$M,13,0) -> 40 | H557: 自制 | I557: 现代起亚
A558: DQ901872 | B558: =VLOOKUP($A558,[1]中含分析60315!$A:$M,8,0) -> 59 | C558: =VLOOKUP($A558,[1]中含分析60315!$A:$M,9,0) -> 58 | D558: =VLOOKUP($A558,[1]中含分析60315!$A:$M,10,0) -> 57 | E558: =VLOOKUP($A558,[1]中含分析60315!$A:$M,11,0) -> 56 | F558: =VLOOKUP($A558,[1]中含分析60315!$A:$M,12,0) -> 56 | G558: =VLOOKUP($A558,[1]中含分析60315!$A:$M,13,0) -> 55 | H558: 调货 | I558: 丰田02272
A559: DQ901877 | B559: =VLOOKUP($A559,[1]中含分析60315!$A:$M,8,0) -> 50 | C559: =VLOOKUP($A559,[1]中含分析60315!$A:$M,9,0) -> 48 | D559: =VLOOKUP($A559,[1]中含分析60315!$A:$M,10,0) -> 46 | E559: =VLOOKUP($A559,[1]中含分析60315!$A:$M,11,0) -> 44 | F559: =VLOOKUP($A559,[1]中含分析60315!$A:$M,12,0) -> 42 | G559: =VLOOKUP($A559,[1]中含分析60315!$A:$M,13,0) -> 41 | H559: 自制 | I559: 雷凌1.5L
A560: DQ9031E1 | B560: =VLOOKUP($A560,[1]中含分析60315!$A:$M,8,0) -> 54 | C560: =VLOOKUP($A560,[1]中含分析60315!$A:$M,9,0) -> 52 | D560: =VLOOKUP($A560,[1]中含分析60315!$A:$M,10,0) -> 50 | E560: =VLOOKUP($A560,[1]中含分析60315!$A:$M,11,0) -> 48 | F560: =VLOOKUP($A560,[1]中含分析60315!$A:$M,12,0) -> 46 | G560: =VLOOKUP($A560,[1]中含分析60315!$A:$M,13,0) -> 44 | H560: 自制 | I560: MG6 1.5T
...

Sheet 中未价60319
A1: 对外型号 | B1: NP中未60319 | C1: LP中未60319 | D1: SLP中未60319 | E1: 2S中未60319 | F1: 3S中未60319 | G1: 4S中未60319 | H1: 属性 | I1: 通用名
A2: DQ910852 | B2: =VLOOKUP($A2,[1]中未分析60315!$A:$M,8,0) -> 35 | C2: =VLOOKUP($A2,[1]中未分析60315!$A:$M,9,0) -> 33 | D2: =VLOOKUP($A2,[1]中未分析60315!$A:$M,10,0) -> 32 | E2: =VLOOKUP($A2,[1]中未分析60315!$A:$M,11,0) -> 31 | F2: =VLOOKUP($A2,[1]中未分析60315!$A:$M,12,0) -> 30 | G2: =VLOOKUP($A2,[1]中未分析60315!$A:$M,13,0) -> 28 | H2: 自制 | I2: 丰田卡罗拉
A3: DQ9101B1 | B3: =VLOOKUP($A3,[1]中未分析60315!$A:$M,8,0) -> 22 | C3: =VLOOKUP($A3,[1]中未分析60315!$A:$M,9,0) -> 21 | D3: =VLOOKUP($A3,[1]中未分析60315!$A:$M,10,0) -> 20 | E3: =VLOOKUP($A3,[1]中未分析60315!$A:$M,11,0) -> 19 | F3: =VLOOKUP($A3,[1]中未分析60315!$A:$M,12,0) -> 18 | G3: =VLOOKUP($A3,[1]中未分析60315!$A:$M,13,0) -> 18 | H3: 自制 | I3: 伽玛发动机
A4: DQ9106L | B4: =VLOOKUP($A4,[1]中未分析60315!$A:$M,8,0) -> 37 | C4: =VLOOKUP($A4,[1]中未分析60315!$A:$M,9,0) -> 36 | D4: =VLOOKUP($A4,[1]中未分析60315!$A:$M,10,0) -> 35 | E4: =VLOOKUP($A4,[1]中未分析60315!$A:$M,11,0) -> 33 | F4: =VLOOKUP($A4,[1]中未分析60315!$A:$M,12,0) -> 32 | G4: =VLOOKUP($A4,[1]中未分析60315!$A:$M,13,0) -> 30 | H4: 自制 | I4: 波罗
A5: DQ9103A | B5: =VLOOKUP($A5,[1]中未分析60315!$A:$M,8,0) -> 40 | C5: =VLOOKUP($A5,[1]中未分析60315!$A:$M,9,0) -> 38 | D5: =VLOOKUP($A5,[1]中未分析60315!$A:$M,10,0) -> 37 | E5: =VLOOKUP($A5,[1]中未分析60315!$A:$M,11,0) -> 35 | F5: =VLOOKUP($A5,[1]中未分析60315!$A:$M,12,0) -> 34 | G5: =VLOOKUP($A5,[1]中未分析60315!$A:$M,13,0) -> 32 | H5: 自制 | I5: 奥迪C6
A6: DQ9101A | B6: =VLOOKUP($A6,[1]中未分析60315!$A:$M,8,0) -> 22 | C6: =VLOOKUP($A6,[1]中未分析60315!$A:$M,9,0) -> 21 | D6: =VLOOKUP($A6,[1]中未分析60315!$A:$M,10,0) -> 20 | E6: =VLOOKUP($A6,[1]中未分析60315!$A:$M,11,0) -> 19 | F6: =VLOOKUP($A6,[1]中未分析60315!$A:$M,12,0) -> 19 | G6: =VLOOKUP($A6,[1]中未分析60315!$A:$M,13,0) -> 18 | H6: 自制 | I6: 伊兰特 VVT 圆头
A7: DQ9115A | B7: =VLOOKUP($A7,[1]中未分析60315!$A:$M,8,0) -> 23 | C7: =VLOOKUP($A7,[1]中未分析60315!$A:$M,9,0) -> 22 | D7: =VLOOKUP($A7,[1]中未分析60315!$A:$M,10,0) -> 21 | E7: =VLOOKUP($A7,[1]中未分析60315!$A:$M,11,0) -> 20 | F7: =VLOOKUP($A7,[1]中未分析60315!$A:$M,12,0) -> 19 | G7: =VLOOKUP($A7,[1]中未分析60315!$A:$M,13,0) -> 19 | H7: 自制 | I7: 4A9
A8: DQ9012 | B8: =VLOOKUP($A8,[1]中未分析60315!$A:$M,8,0) -> 40 | C8: =VLOOKUP($A8,[1]中未分析60315!$A:$M,9,0) -> 38 | D8: =VLOOKUP($A8,[1]中未分析60315!$A:$M,10,0) -> 37 | E8: =VLOOKUP($A8,[1]中未分析60315!$A:$M,11,0) -> 35 | F8: =VLOOKUP($A8,[1]中未分析60315!$A:$M,12,0) -> 34 | G8: =VLOOKUP($A8,[1]中未分析60315!$A:$M,13,0) -> 32 | H8: 自制 | I8: 骐达
A9: DQ9219A | B9: =VLOOKUP($A9,[1]中未分析60315!$A:$M,8,0) -> 27 | C9: =VLOOKUP($A9,[1]中未分析60315!$A:$M,9,0) -> 26 | D9: =VLOOKUP($A9,[1]中未分析60315!$A:$M,10,0) -> 25 | E9: =VLOOKUP($A9,[1]中未分析60315!$A:$M,11,0) -> 24 | F9: =VLOOKUP($A9,[1]中未分析60315!$A:$M,12,0) -> 23 | G9: =VLOOKUP($A9,[1]中未分析60315!$A:$M,13,0) -> 22 | H9: 自制 | I9: 哈弗H6 1.5T
A10: DQ9103D | B10: =VLOOKUP($A10,[1]中未分析60315!$A:$M,8,0) -> 39 | C10: =VLOOKUP($A10,[1]中未分析60315!$A:$M,9,0) -> 38 | D10: =VLOOKUP($A10,[1]中未分析60315!$A:$M,10,0) -> 36 | E10: =VLOOKUP($A10,[1]中未分析60315!$A:$M,11,0) -> 35 | F10: =VLOOKUP($A10,[1]中未分析60315!$A:$M,12,0) -> 34 | G10: =VLOOKUP($A10,[1]中未分析60315!$A:$M,13,0) -> 32 | H10: 自制 | I10: 帕萨特B5 不铣胶面
A11: DQ910848 | B11: =VLOOKUP($A11,[1]中未分析60315!$A:$M,8,0) -> 33 | C11: =VLOOKUP($A11,[1]中未分析60315!$A:$M,9,0) -> 32 | D11: =VLOOKUP($A11,[1]中未分析60315!$A:$M,10,0) -> 31 | E11: =VLOOKUP($A11,[1]中未分析60315!$A:$M,11,0) -> 29 | F11: =VLOOKUP($A11,[1]中未分析60315!$A:$M,12,0) -> 28 | G11: =VLOOKUP($A11,[1]中未分析60315!$A:$M,13,0) -> 27 | H11: 自制 | I11: 丰田02248
A12: DQ9003H2 | B12: =VLOOKUP($A12,[1]中未分析60315!$A:$M,8,0) -> 33 | C12: =VLOOKUP($A12,[1]中未分析60315!$A:$M,9,0) -> 32 | D12: =VLOOKUP($A12,[1]中未分析60315!$A:$M,10,0) -> 30 | E12: =VLOOKUP($A12,[1]中未分析60315!$A:$M,11,0) -> 29 | F12: =VLOOKUP($A12,[1]中未分析60315!$A:$M,12,0) -> 28 | G12: =VLOOKUP($A12,[1]中未分析60315!$A:$M,13,0) -> 27 | H12: 自制 | I12: 尼桑
A13: DQ9401 | B13: =VLOOKUP($A13,[1]中未分析60315!$A:$M,8,0) -> 39 | C13: =VLOOKUP($A13,[1]中未分析60315!$A:$M,9,0) -> 38 | D13: =VLOOKUP($A13,[1]中未分析60315!$A:$M,10,0) -> 36 | E13: =VLOOKUP($A13,[1]中未分析60315!$A:$M,11,0) -> 35 | F13: =VLOOKUP($A13,[1]中未分析60315!$A:$M,12,0) -> 33 | G13: =VLOOKUP($A13,[1]中未分析60315!$A:$M,13,0) -> 32 | H13: 自制 | I13: 德尔福三代
... A473: DQ9003J2 | B473: =VLOOKUP($A473,[1]中未分析60315!$A:$M,8,0) -> 44 | C473: =VLOOKUP($A473,[1]中未分析60315!$A:$M,9,0) -> 43 | D473: =VLOOKUP($A473,[1]中未分析60315!$A:$M,10,0) -> 41 | E473: =VLOOKUP($A473,[1]中未分析60315!$A:$M,11,0) -> 39 | F473: =VLOOKUP($A473,[1]中未分析60315!$A:$M,12,0) -> 38 | G473: =VLOOKUP($A473,[1]中未分析60315!$A:$M,13,0) -> 36 | H473: 自制 | I473: 途乐4.0L
A474: DQ9003K1 | B474: =VLOOKUP($A474,[1]中未分析60315!$A:$M,8,0) -> 52 | C474: =VLOOKUP($A474,[1]中未分析60315!$A:$M,9,0) -> 52 | D474: =VLOOKUP($A474,[1]中未分析60315!$A:$M,10,0) -> 51 | E474: =VLOOKUP($A474,[1]中未分析60315!$A:$M,11,0) -> 50 | F474: =VLOOKUP($A474,[1]中未分析60315!$A:$M,12,0) -> 49 | G474: =VLOOKUP($A474,[1]中未分析60315!$A:$M,13,0) -> 49 | H474: 调货 | I474: 0
A475: DQ9004D2 | B475: =VLOOKUP($A475,[1]中未分析60315!$A:$M,8,0) -> 38 | C475: =VLOOKUP($A475,[1]中未分析60315!$A:$M,9,0) -> 37 | D475: =VLOOKUP($A475,[1]中未分析60315!$A:$M,10,0) -> 35 | E475: =VLOOKUP($A475,[1]中未分析60315!$A:$M,11,0) -> 34 | F475: =VLOOKUP($A475,[1]中未分析60315!$A:$M,12,0) -> 33 | G475: =VLOOKUP($A475,[1]中未分析60315!$A:$M,13,0) -> 31 | H475: 自制 | I475: 尼桑
A476: DQ9005M1 | B476: =VLOOKUP($A476,[1]中未分析60315!$A:$M,8,0) -> 29 | C476: =VLOOKUP($A476,[1]中未分析60315!$A:$M,9,0) -> 28 | D476: =VLOOKUP($A476,[1]中未分析60315!$A:$M,10,0) -> 28 | E476: =VLOOKUP($A476,[1]中未分析60315!$A:$M,11,0) -> 27 | F476: =VLOOKUP($A476,[1]中未分析60315!$A:$M,12,0) -> 27 | G476: =VLOOKUP($A476,[1]中未分析60315!$A:$M,13,0) -> 27 | H476: 调货 | I476: 福特96-99
A477: DQ9007J1 | B477: =VLOOKUP($A477,[1]中未分析60315!$A:$M,8,0) -> 44 | C477: =VLOOKUP($A477,[1]中未分析60315!$A:$M,9,0) -> 42 | D477: =VLOOKUP($A477,[1]中未分析60315!$A:$M,10,0) -> 41 | E477: =VLOOKUP($A477,[1]中未分析60315!$A:$M,11,0) -> 39 | F477: =VLOOKUP($A477,[1]中未分析60315!$A:$M,12,0) -> 37 | G477: =VLOOKUP($A477,[1]中未分析60315!$A:$M,13,0) -> 36 | H477: 自制 | I477: 现代3L030
A478: DQ9007H1 | B478: =VLOOKUP($A478,[1]中未分析60315!$A:$M,8,0) -> 45 | C478: =VLOOKUP($A478,[1]中未分析60315!$A:$M,9,0) -> 43 | D478: =VLOOKUP($A478,[1]中未分析60315!$A:$M,10,0) -> 42 | E478: =VLOOKUP($A478,[1]中未分析60315!$A:$M,11,0) -> 40 | F478: =VLOOKUP($A478,[1]中未分析60315!$A:$M,12,0) -> 38 | G478: =VLOOKUP($A478,[1]中未分析60315!$A:$M,13,0) -> 37 | H478: 自制 | I478: 2019 Kia Cadenza 3.3l
A479: DQ9008A1 | B479: =VLOOKUP($A479,[1]中未分析60315!$A:$M,8,0) -> 45 | C479: =VLOOKUP($A479,[1]中未分析60315!$A:$M,9,0) -> 45 | D479: =VLOOKUP($A479,[1]中未分析60315!$A:$M,10,0) -> 44 | E479: =VLOOKUP($A479,[1]中未分析60315!$A:$M,11,0) -> 43 | F479: =VLOOKUP($A479,[1]中未分析60315!$A:$M,12,0) -> 43 | G479: =VLOOKUP($A479,[1]中未分析60315!$A:$M,13,0) -> 42 | H479: 调货 | I479: 三菱蓝瑟4G93
A480: DQ9008B1 | B480: =VLOOKUP($A480,[1]中未分析60315!$A:$M,8,0) -> 51 | C480: =VLOOKUP($A480,[1]中未分析60315!$A:$M,9,0) -> 50 | D480: =VLOOKUP($A480,[1]中未分析60315!$A:$M,10,0) -> 49 | E480: =VLOOKUP($A480,[1]中未分析60315!$A:$M,11,0) -> 48 | F480: =VLOOKUP($A480,[1]中未分析60315!$A:$M,12,0) -> 48 | G480: =VLOOKUP($A480,[1]中未分析60315!$A:$M,13,0) -> 47 | H480: 调货 | I480: 三菱蓝瑟08-12 2.0L
A481: DQ9010G1 | B481: =VLOOKUP($A481,[1]中未分析60315!$A:$M,8,0) -> 43 | C481: =VLOOKUP($A481,[1]中未分析60315!$A:$M,9,0) -> 42 | D481: =VLOOKUP($A481,[1]中未分析60315!$A:$M,10,0) -> 40 | E481: =VLOOKUP($A481,[1]中未分析60315!$A:$M,11,0) -> 39 | F481: =VLOOKUP($A481,[1]中未分析60315!$A:$M,12,0) -> 37 | G481: =VLOOKUP($A481,[1]中未分析60315!$A:$M,13,0) -> 35 | H481: 自制 | I481: 本田锋范
A482: DQ9010L1 | B482: =VLOOKUP($A482,[1]中未分析60315!$A:$M,8,0) -> 34 | C482: =VLOOKUP($A482,[1]中未分析60315!$A:$M,9,0) -> 33 | D482: =VLOOKUP($A482,[1]中未分析60315!$A:$M,10,0) -> 32 | E482: =VLOOKUP($A482,[1]中未分析60315!$A:$M,11,0) -> 30 | F482: =VLOOKUP($A482,[1]中未分析60315!$A:$M,12,0) -> 29 | G482: =VLOOKUP($A482,[1]中未分析60315!$A:$M,13,0) -> 28 | H482: 自制 | I482: 本田飞度混动2013款
A483: DQ901810 | B483: =VLOOKUP($A483,[1]中未分析60315!$A:$M,8,0) -> 56 | C483: =VLOOKUP($A483,[1]中未分析60315!$A:$M,9,0) -> 55 | D483: =VLOOKUP($A483,[1]中未分析60315!$A:$M,10,0) -> 54 | E483: =VLOOKUP($A483,[1]中未分析60315!$A:$M,11,0) -> 53 | F483: =VLOOKUP($A483,[1]中未分析60315!$A:$M,12,0) -> 53 | G483: =VLOOKUP($A483,[1]中未分析60315!$A:$M,13,0) -> 52 | H483: 调货 | I483: 丰田2017-201818致炫
A484: DQ9024 | B484: =VLOOKUP($A484,[1]中未分析60315!$A:$M,8,0) -> 74 | C484: =VLOOKUP($A484,[1]中未分析60315!$A:$M,9,0) -> 73 | D484: =VLOOKUP($A484,[1]中未分析60315!$A:$M,10,0) -> 71 | E484: =VLOOKUP($A484,[1]中未分析60315!$A:$M,11,0) -> 70 | F484: =VLOOKUP($A484,[1]中未分析60315!$A:$M,12,0) -> 70 | G484: =VLOOKUP($A484,[1]中未分析60315!$A:$M,13,0) -> 68 | H484: 调货 | I484: 竞技 骑兵
A485: DQ9030C1 | B485: =VLOOKUP($A485,[1]中未分析60315!$A:$M,8,0) -> 48 | C485: =VLOOKUP($A485,[1]中未分析60315!$A:$M,9,0) -> 46 | D485: =VLOOKUP($A485,[1]中未分析60315!$A:$M,10,0) -> 44 | E485: =VLOOKUP($A485,[1]中未分析60315!$A:$M,11,0) -> 43 | F485: =VLOOKUP($A485,[1]中未分析60315!$A:$M,12,0) -> 41 | G485: =VLOOKUP($A485,[1]中未分析60315!$A:$M,13,0) -> 39 | H485: 自制 | I485: 长安福特 金牛座2.7T
A486: DQ9034A3 | B486: =VLOOKUP($A486,[1]中未分析60315!$A:$M,8,0) -> 35 | C486: =VLOOKUP($A486,[1]中未分析60315!$A:$M,9,0) -> 33 | D486: =VLOOKUP($A486,[1]中未分析60315!$A:$M,10,0) -> 32 | E486: =VLOOKUP($A486,[1]中未分析60315!$A:$M,11,0) -> 31 | F486: =VLOOKUP($A486,[1]中未分析60315!$A:$M,12,0) -> 30 | G486: =VLOOKUP($A486,[1]中未分析60315!$A:$M,13,0) -> 28 | H486: 自制 | I486: 纳智捷TT26S
... A548: DQ4202A1 | B548: =VLOOKUP($A548,[1]中未分析60315!$A:$M,8,0) -> 60 | C548: =VLOOKUP($A548,[1]中未分析60315!$A:$M,9,0) -> 59 | D548: =VLOOKUP($A548,[1]中未分析60315!$A:$M,10,0) -> 58 | E548: =VLOOKUP($A548,[1]中未分析60315!$A:$M,11,0) -> 57 | F548: =VLOOKUP($A548,[1]中未分析60315!$A:$M,12,0) -> 56 | G548: =VLOOKUP($A548,[1]中未分析60315!$A:$M,13,0) -> 55 | H548: 调货 | I548: 丰田SR40
A549: DQ4106A1 | B549: =VLOOKUP($A549,[1]中未分析60315!$A:$M,8,0) -> 45 | C549: =VLOOKUP($A549,[1]中未分析60315!$A:$M,9,0) -> 43 | D549: =VLOOKUP($A549,[1]中未分析60315!$A:$M,10,0) -> 41 | E549: =VLOOKUP($A549,[1]中未分析60315!$A:$M,11,0) -> 40 | F549: =VLOOKUP($A549,[1]中未分析60315!$A:$M,12,0) -> 38 | G549: =VLOOKUP($A549,[1]中未分析60315!$A:$M,13,0) -> 36 | H549: 自制 | I549: 12713668
A550: DQ4115A1 | B550: =VLOOKUP($A550,[1]中未分析60315!$A:$M,8,0) -> 39 | C550: =VLOOKUP($A550,[1]中未分析60315!$A:$M,9,0) -> 39 | D550: =VLOOKUP($A550,[1]中未分析60315!$A:$M,10,0) -> 38 | E550: =VLOOKUP($A550,[1]中未分析60315!$A:$M,11,0) -> 37 | F550: =VLOOKUP($A550,[1]中未分析60315!$A:$M,12,0) -> 37 | G550: =VLOOKUP($A550,[1]中未分析60315!$A:$M,13,0) -> 36 | H550: 调货 | I550: 90919-02098
A551: DQ4119A1 | B551: =VLOOKUP($A551,[1]中未分析60315!$A:$M,8,0) -> 40 | C551: =VLOOKUP($A551,[1]中未分析60315!$A:$M,9,0) -> 39 | D551: =VLOOKUP($A551,[1]中未分析60315!$A:$M,10,0) -> 39 | E551: =VLOOKUP($A551,[1]中未分析60315!$A:$M,11,0) -> 38 | F551: =VLOOKUP($A551,[1]中未分析60315!$A:$M,12,0) -> 38 | G551: =VLOOKUP($A551,[1]中未分析60315!$A:$M,13,0) -> 37 | H551: 调货 | I551: 马自达MX-3
A552: DQ4120A1 | B552: =VLOOKUP($A552,[1]中未分析60315!$A:$M,8,0) -> 59 | C552: =VLOOKUP($A552,[1]中未分析60315!$A:$M,9,0) -> 58 | D552: =VLOOKUP($A552,[1]中未分析60315!$A:$M,10,0) -> 57 | E552: =VLOOKUP($A552,[1]中未分析60315!$A:$M,11,0) -> 56 | F552: =VLOOKUP($A552,[1]中未分析60315!$A:$M,12,0) -> 55 | G552: =VLOOKUP($A552,[1]中未分析60315!$A:$M,13,0) -> 54 | H552: 调货 | I552: 雷克萨斯
A553: DQ4402A1 | B553: =VLOOKUP($A553,[1]中未分析60315!$A:$M,8,0) -> 79 | C553: =VLOOKUP($A553,[1]中未分析60315!$A:$M,9,0) -> 78 | D553: =VLOOKUP($A553,[1]中未分析60315!$A:$M,10,0) -> 76 | E553: =VLOOKUP($A553,[1]中未分析60315!$A:$M,11,0) -> 75 | F553: =VLOOKUP($A553,[1]中未分析60315!$A:$M,12,0) -> 74 | G553: =VLOOKUP($A553,[1]中未分析60315!$A:$M,13,0) -> 73 | H553: 调货 | I553: 起亚EIO L4
A554: DQ9003G7 | B554: =VLOOKUP($A554,[1]中未分析60315!$A:$M,8,0) -> 46 | C554: =VLOOKUP($A554,[1]中未分析60315!$A:$M,9,0) -> 45 | D554: =VLOOKUP($A554,[1]中未分析60315!$A:$M,10,0) -> 45 | E554: =VLOOKUP($A554,[1]中未分析60315!$A:$M,11,0) -> 44 | F554: =VLOOKUP($A554,[1]中未分析60315!$A:$M,12,0) -> 44 | G554: =VLOOKUP($A554,[1]中未分析60315!$A:$M,13,0) -> 43 | H554: 调货 | I554: 22448-6LBOA
A555: DQ9007K1 | B555: =VLOOKUP($A555,[1]中未分析60315!$A:$M,8,0) -> 44 | C555: =VLOOKUP($A555,[1]中未分析60315!$A:$M,9,0) -> 43 | D555: =VLOOKUP($A555,[1]中未分析60315!$A:$M,10,0) -> 41 | E555: =VLOOKUP($A555,[1]中未分析60315!$A:$M,11,0) -> 40 | F555: =VLOOKUP($A555,[1]中未分析60315!$A:$M,12,0) -> 38 | G555: =VLOOKUP($A555,[1]中未分析60315!$A:$M,13,0) -> 36 | H555: 自制 | I555: 现代起亚
A556: DQ9007M1 | B556: =VLOOKUP($A556,[1]中未分析60315!$A:$M,8,0) -> 47 | C556: =VLOOKUP($A556,[1]中未分析60315!$A:$M,9,0) -> 45 | D556: =VLOOKUP($A556,[1]中未分析60315!$A:$M,10,0) -> 44 | E556: =VLOOKUP($A556,[1]中未分析60315!$A:$M,11,0) -> 42 | F556: =VLOOKUP($A556,[1]中未分析60315!$A:$M,12,0) -> 40 | G556: =VLOOKUP($A556,[1]中未分析60315!$A:$M,13,0) -> 39 | H556: 自制 | I556: 现代伊兰特
A557: DQ9007Q1 | B557: =VLOOKUP($A557,[1]中未分析60315!$A:$M,8,0) -> 46 | C557: =VLOOKUP($A557,[1]中未分析60315!$A:$M,9,0) -> 45 | D557: =VLOOKUP($A557,[1]中未分析60315!$A:$M,10,0) -> 43 | E557: =VLOOKUP($A557,[1]中未分析60315!$A:$M,11,0) -> 41 | F557: =VLOOKUP($A557,[1]中未分析60315!$A:$M,12,0) -> 40 | G557: =VLOOKUP($A557,[1]中未分析60315!$A:$M,13,0) -> 38 | H557: 自制 | I557: 现代起亚
A558: DQ901872 | B558: =VLOOKUP($A558,[1]中未分析60315!$A:$M,8,0) -> 57 | C558: =VLOOKUP($A558,[1]中未分析60315!$A:$M,9,0) -> 56 | D558: =VLOOKUP($A558,[1]中未分析60315!$A:$M,10,0) -> 55 | E558: =VLOOKUP($A558,[1]中未分析60315!$A:$M,11,0) -> 54 | F558: =VLOOKUP($A558,[1]中未分析60315!$A:$M,12,0) -> 53 | G558: =VLOOKUP($A558,[1]中未分析60315!$A:$M,13,0) -> 52 | H558: 调货 | I558: 丰田02272
A559: DQ901877 | B559: =VLOOKUP($A559,[1]中未分析60315!$A:$M,8,0) -> 46 | C559: =VLOOKUP($A559,[1]中未分析60315!$A:$M,9,0) -> 44 | D559: =VLOOKUP($A559,[1]中未分析60315!$A:$M,10,0) -> 43 | E559: =VLOOKUP($A559,[1]中未分析60315!$A:$M,11,0) -> 41 | F559: =VLOOKUP($A559,[1]中未分析60315!$A:$M,12,0) -> 39 | G559: =VLOOKUP($A559,[1]中未分析60315!$A:$M,13,0) -> 38 | H559: 自制 | I559: 雷凌1.5L
A560: DQ9031E1 | B560: =VLOOKUP($A560,[1]中未分析60315!$A:$M,8,0) -> 50 | C560: =VLOOKUP($A560,[1]中未分析60315!$A:$M,9,0) -> 48 | D560: =VLOOKUP($A560,[1]中未分析60315!$A:$M,10,0) -> 47 | E560: =VLOOKUP($A560,[1]中未分析60315!$A:$M,11,0) -> 45 | F560: =VLOOKUP($A560,[1]中未分析60315!$A:$M,12,0) -> 43 | G560: =VLOOKUP($A560,[1]中未分析60315!$A:$M,13,0) -> 41 | H560: 自制 | I560: MG6 1.5T
...
